Workbook
Name EURIBOR_ULTIMO: 'Parámetros'!$C$8
Name COM_FIJO_10: 'Parámetros'!$C$10
Name COM_FIJO_RESTO: 'Parámetros'!$C$11
Name COM_VAR_A: 'Parámetros'!$C$12
Name COM_VAR_A_ANIOS: 'Parámetros'!$C$13
Name COM_VAR_B: 'Parámetros'!$C$14
Name COM_VAR_B_ANIOS: 'Parámetros'!$C$15
Name COM_VAR_DESPUES: 'Parámetros'!$C$16
Name ESFUERZO: 'Parámetros'!$C$18
Name CAPITAL: 'Tu hipoteca'!$C$8
Name PLAZO: 'Tu hipoteca'!$C$9
Name EURIBOR_HOY: 'Tu hipoteca'!$C$10
Name ESCENARIO: 'Tu hipoteca'!$C$11
Name EURIBOR_PERS: 'Tu hipoteca'!$C$12
Name INGRESOS: 'Tu hipoteca'!$C$13
Name EURIBOR: 'Tu hipoteca'!$C$15
Name MESES: 'Tu hipoteca'!$C$16
Name OF_BANCO_1: 'Ofertas'!$D$9
Name OF_BANCO_2: 'Ofertas'!$E$9
Name OF_BANCO_3: 'Ofertas'!$F$9
Name OF_BANCO_4: 'Ofertas'!$G$9
Name OF_TIPO_1: 'Ofertas'!$D$10
Name OF_TIPO_2: 'Ofertas'!$E$10
Name OF_TIPO_3: 'Ofertas'!$F$10
Name OF_TIPO_4: 'Ofertas'!$G$10
Name OF_TIN_1: 'Ofertas'!$D$11
Name OF_TIN_2: 'Ofertas'!$E$11
Name OF_TIN_3: 'Ofertas'!$F$11
Name OF_TIN_4: 'Ofertas'!$G$11
Name OF_ANIOS_INI_1: 'Ofertas'!$D$12
Name OF_ANIOS_INI_2: 'Ofertas'!$E$12
Name OF_ANIOS_INI_3: 'Ofertas'!$F$12
Name OF_ANIOS_INI_4: 'Ofertas'!$G$12
Name OF_DIF_1: 'Ofertas'!$D$13
Name OF_DIF_2: 'Ofertas'!$E$13
Name OF_DIF_3: 'Ofertas'!$F$13
Name OF_DIF_4: 'Ofertas'!$G$13
Name OF_SIN_1: 'Ofertas'!$D$14
Name OF_SIN_2: 'Ofertas'!$E$14
Name OF_SIN_3: 'Ofertas'!$F$14
Name OF_SIN_4: 'Ofertas'!$G$14
Name OF_APERTURA_1: 'Ofertas'!$D$15
Name OF_APERTURA_2: 'Ofertas'!$E$15
Name OF_APERTURA_3: 'Ofertas'!$F$15
Name OF_APERTURA_4: 'Ofertas'!$G$15
Name OF_TASACION_1: 'Ofertas'!$D$16
Name OF_TASACION_2: 'Ofertas'!$E$16
Name OF_TASACION_3: 'Ofertas'!$F$16
Name OF_TASACION_4: 'Ofertas'!$G$16
Name OF_OTROS_1: 'Ofertas'!$D$17
Name OF_OTROS_2: 'Ofertas'!$E$17
Name OF_OTROS_3: 'Ofertas'!$F$17
Name OF_OTROS_4: 'Ofertas'!$G$17
Name OF_VIDA_1: 'Ofertas'!$D$18
Name OF_VIDA_2: 'Ofertas'!$E$18
Name OF_VIDA_3: 'Ofertas'!$F$18
Name OF_VIDA_4: 'Ofertas'!$G$18
Name OF_HOGAR_1: 'Ofertas'!$D$19
Name OF_HOGAR_2: 'Ofertas'!$E$19
Name OF_HOGAR_3: 'Ofertas'!$F$19

Sheet Portada
C3: HOGARCLARO
C5: Comparador de hipotecas para negociar
C7: Pon hasta cuatro ofertas (FEIN) una al lado de otra y mira lo que de verdad te cuesta cada una: TAE con seguros, vinculaciones, escenarios de Euríbor y amortizar antes.
C10: Edición 2027 · Euríbor de septiembre de 2026: 3,247 %
C14: Empieza en tres pasos
B15: 1 | C15: En «Tu hipoteca» pon el importe, el plazo y el escenario de Euríbor.
B16: 2 | C16: En «Ofertas» copia los datos de cada FEIN: tipo, TIN, diferencial, comisiones, seguros y productos vinculados.
B17: 3 | C17: Mira «Comparativa»: coste total, TAE real y cuál conviene. Lleva al banco las preguntas del PDF.
C19: Qué hay en este libro
C20: → Comparativa | D20: Las cuatro ofertas resumidas, ordenadas por coste total, con gráfico
C21: → Tu hipoteca | D21: Importe, plazo y escenario de Euríbor
C22: → Ofertas | D22: Los datos de cada FEIN y sus resultados
C23: → Escenarios Euríbor | D23: Cuánto pagarías si el Euríbor baja o sube
C24: → Amortizar antes | D24: Reducir cuota o plazo: ahorro y comisión legal
C25: → Cuadro anual | D25: Cuadro de amortización por años de la oferta que elijas
C26: → Cuadro mensual | D26: Mes a mes de las cuatro ofertas (lo usan las demás hojas)
C27: → Parámetros | D27: Euríbor y topes legales con su fuente
C29: Antes de usarlo
C30: Cálculo orientativo para comparar ofertas: la TAE oficial de la FEIN (Orden EHA/2899/2011) puede diferir unas centésimas. No es asesoramiento financiero.
C31: El Euríbor por defecto es la media de septiembre de 2026 (3.247 %). Cámbialo o elige un escenario: nadie sabe cuánto valdrá.
C32: Contenido preparado con ayuda de inteligencia artificial y revisado con las fuentes oficiales citadas (Ley 5/2019, Banco de España, BOE).
C33: Funciona en Excel, LibreOffice y Google Sheets. Las hojas de cálculo están protegidas sin contraseña: Revisar → Desproteger hoja.
C35: https://hogarclaro.vercel.app/comparador-hipotecas-excel/ | D35: Contacto: hola@numimates.com

Sheet Instrucciones
B2: Cómo se usa el comparador | C2: HogarClaro
B3: Léelo una vez: son cinco minutos
B6: 1. Pide la FEIN
B7: • | C7: La Ficha Europea de Información Normalizada es obligatoria y gratuita: el banco te la tiene que dar con las condiciones personalizadas y al menos 10 días naturales antes de firmar (Ley 5/2019, art. 14). Pídela a cada banco aunque solo estés comparando.
B8: • | C8: De la FEIN necesitas: tipo de interés (TIN) con y sin bonificaciones, diferencial si es variable, años a tipo fijo si es mixta, comisiones, gastos de tasación y el precio de los seguros y productos que te exigen para bonificar.
B10: 2. Rellena las ofertas
B11: • | C11: Fija: el TIN de todo el plazo. Mixta: el TIN de los años fijos, cuántos años son y el diferencial sobre el Euríbor del resto. Variable: el tipo del primer año (pon 1 en años iniciales) y el diferencial.
B12: • | C12: Seguros: el precio anual de vida y hogar si los contratas con el banco para bonificar. Otros vinculados: lo que cuestan al mes la cuenta, la tarjeta, el plan de pensiones o la nómina que te piden.
B13: • | C13: TIN o diferencial sin bonificar: el que tendrías sin contratar nada. El comparador te dice si bonificarte compensa.
B15: 3. Lee los resultados
B16: • | C16: Coste total = intereses + seguros y vinculaciones + gastos iniciales. Es la cifra para comparar. La TAE aproximada incluye las vinculaciones que pongas, así que puede ser más alta que la de la FEIN.
B17: • | C17: En las variables y mixtas, la cuota después del periodo inicial depende del Euríbor: mira «Escenarios Euríbor» para ver cuánto subiría.
B19: 4. Amortizar antes
B20: • | C20: En «Amortizar antes» elige la oferta, el año y el importe: verás cuánto ahorras reduciendo cuota o plazo y la comisión máxima que permite la ley.
B22: Qué no hace
B23: • | C23: No incluye la subida de las primas con la edad, la revisión de los seguros ni los cambios de condiciones a mitad del préstamo. Cálculo orientativo para comparar ofertas: la TAE oficial de la FEIN (Orden EHA/2899/2011) puede diferir unas centésimas. No es asesoramiento financiero.
B25: Ayuda
B26: • | C26: ¿Algo no cuadra? Escribe a hola@numimates.com.

Sheet Comparativa
B2: Comparativa | F2: HogarClaro
B3: ="Préstamo de "&FIXED(CAPITAL,0)&" € a "&PLAZO&" años · Euríbor "&EURIBOR&" %"
C7: =IF(OF_BANCO_1="","Oferta 1",OF_BANCO_1) | D7: =IF(OF_BANCO_2="","Oferta 2",OF_BANCO_2) | E7: =IF(OF_BANCO_3="","Oferta 3",OF_BANCO_3) | F7: =IF(OF_BANCO_4="","Oferta 4",OF_BANCO_4)
B8: Tipo | C8: =IF(BANCO_OK_1,OF_TIPO_1&IF(OF_TIPO_1="Fija"," "&OF_TIN_1&" %"," · "&OF_ANIOS_INI_1&IF(OF_ANIOS_INI_1=1," año"," años")&" + Euríbor + "&OF_DIF_1),"") | D8: =IF(BANCO_OK_2,OF_TIPO_2&IF(OF_TIPO_2="Fija"," "&OF_TIN_2&" %"," · "&OF_ANIOS_INI_2&IF(OF_ANIOS_INI_2=1," año"," años")&" + Euríbor + "&OF_DIF_2),"") | E8: =IF(BANCO_OK_3,OF_TIPO_3&IF(OF_TIPO_3="Fija"," "&OF_TIN_3&" %"," · "&OF_ANIOS_INI_3&IF(OF_ANIOS_INI_3=1," año"," años")&" + Euríbor + "&OF_DIF_3),"") | F8: =IF(BANCO_OK_4,OF_TIPO_4&IF(OF_TIPO_4="Fija"," "&OF_TIN_4&" %"," · "&OF_ANIOS_INI_4&IF(OF_ANIOS_INI_4=1," año"," años")&" + Euríbor + "&OF_DIF_4),"")
B9: Cuota inicial | C9: =CUOTA1_1 | D9: =CUOTA1_2 | E9: =CUOTA1_3 | F9: =CUOTA1_4
B10: Cuota después del periodo inicial | C10: =CUOTA2_1 | D10: =CUOTA2_2 | E10: =CUOTA2_3 | F10: =CUOTA2_4
B11: Seguros y vinculados al mes | C11: =VINCMES_1 | D11: =VINCMES_2 | E11: =VINCMES_3 | F11: =VINCMES_4
B12: TAE aproximada (con vinculaciones) | C12: =TAE_1 | D12: =TAE_2 | E12: =TAE_3 | F12: =TAE_4
B13: Intereses totales | C13: =INTERESES_1 | D13: =INTERESES_2 | E13: =INTERESES_3 | F13: =INTERESES_4
B14: Vinculaciones totales | C14: =VINCTOT_1 | D14: =VINCTOT_2 | E14: =VINCTOT_3 | F14: =VINCTOT_4
B15: Gastos iniciales | C15: =GASTOS_1 | D15: =GASTOS_2 | E15: =GASTOS_3 | F15: =GASTOS_4
B16: COSTE TOTAL | C16: =COSTE_1 | D16: =COSTE_2 | E16: =COSTE_3 | F16: =COSTE_4
B17: ¿Compensa bonificarte? | C17: =COMPENSA_1 | D17: =COMPENSA_2 | E17: =COMPENSA_3 | F17: =COMPENSA_4
B18: Posición | C18: =RANK_1 | D18: =RANK_2 | E18: =RANK_3 | F18: =RANK_4
B20: =IF(COUNT(C16:F16)<2,"Rellena al menos dos ofertas para compararlas.","La más barata en todo el plazo es "&INDEX(C7:F7,MATCH(MIN(C16:F16),C16:F16,0))&": "&FIXED(MIN(C16:F16),0)&" € de coste total.")
B38: Cálculo orientativo para comparar ofertas: la TAE oficial de la FEIN (Orden EHA/2899/2011) puede diferir unas centésimas. No es asesoramiento financiero.

Sheet Tu hipoteca
B2: Tu hipoteca | D2: HogarClaro
B3: Lo común a todas las ofertas
B6: ✎ Las celdas amarillas las rellenas tú; el resto se calcula solo.
B8: Importe del préstamo (€) | C8: 180000 | D8: Lo que te presta el banco (no el precio de la casa).
B9: Plazo (años) | C9: 30 | D9: Hasta 40 años.
B10: Euríbor de partida (%) | C10: =EURIBOR_ULTIMO | D10: Último dato publicado: septiembre de 2026. Cámbialo si quieres.
B11: Escenario de Euríbor para después del periodo inicial | C11: Euríbor de hoy | D11: Se supone constante durante todo el préstamo.
B12: Euríbor personalizado (%) | C12: 3.5 | D12: Solo si eliges «Personalizado».
B13: Tus ingresos netos al mes (opcional) (€) | C13: 3200 | D13: ="Para ver el esfuerzo: los bancos suelen pedir que la cuota no pase del "&ESFUERZO&" %."
B15: Euríbor que se usa en los cálculos (%) | C15: =CHOOSE(MATCH(ESCENARIO,{"Euríbor de hoy","Baja 1 punto","Sube 1 punto","Sube 2 puntos","Personalizado"},0),EURIBOR_HOY,EURIBOR_HOY-1,EURIBOR_HOY+1,EURIBOR_HOY+2,EURIBOR_PERS)
B16: Meses del préstamo | C16: =MIN(480,ROUND(PLAZO*12,0))
B18: Cálculo orientativo para comparar ofertas: la TAE oficial de la FEIN (Orden EHA/2899/2011) puede diferir unas centésimas. No es asesoramiento financiero.

Sheet Ofertas
B2: Las ofertas | G2: HogarClaro
B3: Una columna por FEIN
B6: ✎ Las celdas amarillas las rellenas tú; el resto se calcula solo.
D8: Oferta 1 | E8: Oferta 2 | F8: Oferta 3 | G8: Oferta 4
B9: Banco u oferta
B10: Tipo de interés | D10: Fija | E10: Mixta | F10: Variable | G10: Fija
B11: TIN con bonificaciones (fija) o del periodo inicial (%)
B12: Años del periodo inicial (mixta o variable)
B13: Diferencial sobre el Euríbor con bonificaciones (%)
B14: TIN (fija) o diferencial (variable) SIN bonificar (%)
B15: Comisión de apertura (%)
B16: Tasación a tu cargo (€)
B17: Otros gastos a tu cargo (€)
B18: Seguro de vida vinculado (€ al año)
B19: Seguro de hogar vinculado (€ al año)
B20: Otros productos vinculados (€ al mes)
B21: Comisión por amortizar antes (%) | D21: =IF(D10="Fija",COM_FIJO_10,COM_VAR_A) | E21: =IF(E10="Fija",COM_FIJO_10,COM_VAR_A) | F21: =IF(F10="Fija",COM_FIJO_10,COM_VAR_A) | G21: =IF(G10="Fija",COM_FIJO_10,COM_VAR_A)
B23: Resultados | D23: Oferta 1 | E23: Oferta 2 | F23: Oferta 3 | G23: Oferta 4
B24: Cuota inicial (€ al mes) | D24: =IF(BANCO_OK_1,'Cuadro mensual'!E9,"") | E24: =IF(BANCO_OK_2,'Cuadro mensual'!K9,"") | F24: =IF(BANCO_OK_3,'Cuadro mensual'!Q9,"") | G24: =IF(BANCO_OK_4,'Cuadro mensual'!W9,"")
B25: Cuota después del periodo inicial (escenario) | D25: =IF(BANCO_OK_1,IF(D10="Fija",CUOTA1_1,INDEX('Cuadro mensual'!$E$9:$E$488,MIN(MESES,D12*12+1))),"") | E25: =IF(BANCO_OK_2,IF(E10="Fija",CUOTA1_2,INDEX('Cuadro mensual'!$K$9:$K$488,MIN(MESES,E12*12+1))),"") | F25: =IF(BANCO_OK_3,IF(F10="Fija",CUOTA1_3,INDEX('Cuadro mensual'!$Q$9:$Q$488,MIN(MESES,F12*12+1))),"") | G25: =IF(BANCO_OK_4,IF(G10="Fija",CUOTA1_4,INDEX('Cuadro mensual'!$W$9:$W$488,MIN(MESES,G12*12+1))),"")
B26: Seguros y vinculaciones (€ al mes) | D26: =IF(BANCO_OK_1,(D18+D19)/12+D20,"") | E26: =IF(BANCO_OK_2,(E18+E19)/12+E20,"") | F26: =IF(BANCO_OK_3,(F18+F19)/12+F20,"") | G26: =IF(BANCO_OK_4,(G18+G19)/12+G20,"")
B27: Gastos iniciales a tu cargo | D27: =IF(BANCO_OK_1,CAPITAL*D15/100+D16+D17,"") | E27: =IF(BANCO_OK_2,CAPITAL*E15/100+E16+E17,"") | F27: =IF(BANCO_OK_3,CAPITAL*F15/100+F16+F17,"") | G27: =IF(BANCO_OK_4,CAPITAL*G15/100+G16+G17,"")
B28: Intereses de todo el préstamo | D28: =IF(BANCO_OK_1,SUM('Cuadro mensual'!$F$9:$F$488),"") | E28: =IF(BANCO_OK_2,SUM('Cuadro mensual'!$L$9:$L$488),"") | F28: =IF(BANCO_OK_3,SUM('Cuadro mensual'!$R$9:$R$488),"") | G28: =IF(BANCO_OK_4,SUM('Cuadro mensual'!$X$9:$X$488),"")
B29: Seguros y vinculaciones de todo el plazo | D29: =IF(BANCO_OK_1,VINC_MES_1*MESES,"") | E29: =IF(BANCO_OK_2,VINC_MES_2*MESES,"") | F29: =IF(BANCO_OK_3,VINC_MES_3*MESES,"") | G29: =IF(BANCO_OK_4,VINC_MES_4*MESES,"")
B30: COSTE TOTAL (intereses + vinculaciones + gastos) | D30: =IF(BANCO_OK_1,INTERESES_1+VINC_TOT_1+GASTOS_1,"") | E30: =IF(BANCO_OK_2,INTERESES_2+VINC_TOT_2+GASTOS_2,"") | F30: =IF(BANCO_OK_3,INTERESES_3+VINC_TOT_3+GASTOS_3,"") | G30: =IF(BANCO_OK_4,INTERESES_4+VINC_TOT_4+GASTOS_4,"")
B31: TAE aproximada con las vinculaciones | D31: =IF(BANCO_OK_1,((1+IRR('Cuadro mensual'!$I$8:$I$488,0.003))^12-1)*100,"") | E31: =IF(BANCO_OK_2,((1+IRR('Cuadro mensual'!$O$8:$O$488,0.003))^12-1)*100,"") | F31: =IF(BANCO_OK_3,((1+IRR('Cuadro mensual'!$U$8:$U$488,0.003))^12-1)*100,"") | G31: =IF(BANCO_OK_4,((1+IRR('Cuadro mensual'!$AA$8:$AA$488,0.003))^12-1)*100,"")
B32: Coste total sin bonificar (aprox., tipo constante) | D32: =IF(BANCO_OK_1,PMT(IF(D10="Fija",D14,MAX(0,EURIBOR+D14))/1200,MESES,-CAPITAL)*MESES-CAPITAL+GASTOS_1,"") | E32: =IF(BANCO_OK_2,PMT(IF(E10="Fija",E14,MAX(0,EURIBOR+E14))/1200,MESES,-CAPITAL)*MESES-CAPITAL+GASTOS_2,"") | F32: =IF(BANCO_OK_3,PMT(IF(F10="Fija",F14,MAX(0,EURIBOR+F14))/1200,MESES,-CAPITAL)*MESES-CAPITAL+GASTOS_3,"") | G32: =IF(BANCO_OK_4,PMT(IF(G10="Fija",G14,MAX(0,EURIBOR+G14))/1200,MESES,-CAPITAL)*MESES-CAPITAL+GASTOS_4,"")
B33: ¿Compensa bonificarte? | D33: =IF(BANCO_OK_1,IF(D14="","—",IF(ABS(COSTE_1-SINBON_1)<1,"Sin diferencia",IF(COSTE_1<SINBON_1,"Sí, ahorras "&FIXED(SINBON_1-COSTE_1,0)&" €","No: te cuesta "&FIXED(COSTE_1-SINBON_1,0)&" € más"))),"") | E33: =IF(BANCO_OK_2,IF(E14="","—",IF(ABS(COSTE_2-SINBON_2)<1,"Sin diferencia",IF(COSTE_2<SINBON_2,"Sí, ahorras "&FIXED(SINBON_2-COSTE_2,0)&" €","No: te cuesta "&FIXED(COSTE_2-SINBON_2,0)&" € más"))),"") | F33: =IF(BANCO_OK_3,IF(F14="","—",IF(ABS(COSTE_3-SINBON_3)<1,"Sin diferencia",IF(COSTE_3<SINBON_3,"Sí, ahorras "&FIXED(SINBON_3-COSTE_3,0)&" €","No: te cuesta "&FIXED(COSTE_3-SINBON_3,0)&" € más"))),"") | G33: =IF(BANCO_OK_4,IF(G14="","—",IF(ABS(COSTE_4-SINBON_4)<1,"Sin diferencia",IF(COSTE_4<SINBON_4,"Sí, ahorras "&FIXED(SINBON_4-COSTE_4,0)&" €","No: te cuesta "&FIXED(COSTE_4-SINBON_4,0)&" € más"))),"")
B34: Esfuerzo: cuota + vinculaciones sobre tus ingresos | D34: =IF(BANCO_OK_1,IF(INGRESOS>0,(CUOTA1_1+VINC_MES_1)/INGRESOS,""),"") | E34: =IF(BANCO_OK_2,IF(INGRESOS>0,(CUOTA1_2+VINC_MES_2)/INGRESOS,""),"") | F34: =IF(BANCO_OK_3,IF(INGRESOS>0,(CUOTA1_3+VINC_MES_3)/INGRESOS,""),"") | G34: =IF(BANCO_OK_4,IF(INGRESOS>0,(CUOTA1_4+VINC_MES_4)/INGRESOS,""),"")
B35: Posición por coste total | D35: =IF(BANCO_OK_1,RANK(COSTE_1,RANK_RANGO,1),"") | E35: =IF(BANCO_OK_2,RANK(COSTE_2,RANK_RANGO,1),"") | F35: =IF(BANCO_OK_3,RANK(COSTE_3,RANK_RANGO,1),"") | G35: =IF(BANCO_OK_4,RANK(COSTE_4,RANK_RANGO,1),"")
B36: (oferta rellenada) | D36: =ISNUMBER(D11) | E36: =ISNUMBER(E11) | F36: =ISNUMBER(F11) | G36: =ISNUMBER(G11)
B38: Cálculo orientativo para comparar ofertas: la TAE oficial de la FEIN (Orden EHA/2899/2011) puede diferir unas centésimas. No es asesoramiento financiero. «Sin bonificar» usa un tipo constante (en las variables, el Euríbor del escenario más el diferencial sin bonificar).

Sheet Escenarios Euríbor
B2: Escenarios de Euríbor | G2: HogarClaro
B3: Cuota después del periodo inicial con distintos Euríbor (constantes)
B6: ✎ Las celdas amarillas las rellenas tú; el resto se calcula solo.
B8: Euríbor | C8: Cambio (puntos) | D8: =IF(OF_BANCO_1="","Oferta 1",OF_BANCO_1) | E8: =IF(OF_BANCO_2="","Oferta 2",OF_BANCO_2) | F8: =IF(OF_BANCO_3="","Oferta 3",OF_BANCO_3) | G8: =IF(OF_BANCO_4="","Oferta 4",OF_BANCO_4)
B9: =EURIBOR_HOY+C9 | C9: -1 | D9: =IF(NOT(BANCO_OK_1),"",IF(OF_TIPO_1="Fija",CUOTA1_1,PMT(MAX(0,B9+OF_DIF_1)/1200,MESES-OF_ANIOS_INI_1*12,-IF(OF_ANIOS_INI_1=0,CAPITAL,INDEX(CMES_PEND_1,MIN(MESES,OF_ANIOS_INI_1*12)))))) | E9: =IF(NOT(BANCO_OK_2),"",IF(OF_TIPO_2="Fija",CUOTA1_2,PMT(MAX(0,B9+OF_DIF_2)/1200,MESES-OF_ANIOS_INI_2*12,-IF(OF_ANIOS_INI_2=0,CAPITAL,INDEX(CMES_PEND_2,MIN(MESES,OF_ANIOS_INI_2*12)))))) | F9: =IF(NOT(BANCO_OK_3),"",IF(OF_TIPO_3="Fija",CUOTA1_3,PMT(MAX(0,B9+OF_DIF_3)/1200,MESES-OF_ANIOS_INI_3*12,-IF(OF_ANIOS_INI_3=0,CAPITAL,INDEX(CMES_PEND_3,MIN(MESES,OF_ANIOS_INI_3*12)))))) | G9: =IF(NOT(BANCO_OK_4),"",IF(OF_TIPO_4="Fija",CUOTA1_4,PMT(MAX(0,B9+OF_DIF_4)/1200,MESES-OF_ANIOS_INI_4*12,-IF(OF_ANIOS_INI_4=0,CAPITAL,INDEX(CMES_PEND_4,MIN(MESES,OF_ANIOS_INI_4*12))))))
B10: =EURIBOR_HOY+C10 | C10: 0 | D10: =IF(NOT(BANCO_OK_1),"",IF(OF_TIPO_1="Fija",CUOTA1_1,PMT(MAX(0,B10+OF_DIF_1)/1200,MESES-OF_ANIOS_INI_1*12,-IF(OF_ANIOS_INI_1=0,CAPITAL,INDEX(CMES_PEND_1,MIN(MESES,OF_ANIOS_INI_1*12)))))) | E10: =IF(NOT(BANCO_OK_2),"",IF(OF_TIPO_2="Fija",CUOTA1_2,PMT(MAX(0,B10+OF_DIF_2)/1200,MESES-OF_ANIOS_INI_2*12,-IF(OF_ANIOS_INI_2=0,CAPITAL,INDEX(CMES_PEND_2,MIN(MESES,OF_ANIOS_INI_2*12)))))) | F10: =IF(NOT(BANCO_OK_3),"",IF(OF_TIPO_3="Fija",CUOTA1_3,PMT(MAX(0,B10+OF_DIF_3)/1200,MESES-OF_ANIOS_INI_3*12,-IF(OF_ANIOS_INI_3=0,CAPITAL,INDEX(CMES_PEND_3,MIN(MESES,OF_ANIOS_INI_3*12)))))) | G10: =IF(NOT(BANCO_OK_4),"",IF(OF_TIPO_4="Fija",CUOTA1_4,PMT(MAX(0,B10+OF_DIF_4)/1200,MESES-OF_ANIOS_INI_4*12,-IF(OF_ANIOS_INI_4=0,CAPITAL,INDEX(CMES_PEND_4,MIN(MESES,OF_ANIOS_INI_4*12))))))
B11: =EURIBOR_HOY+C11 | C11: 1 | D11: =IF(NOT(BANCO_OK_1),"",IF(OF_TIPO_1="Fija",CUOTA1_1,PMT(MAX(0,B11+OF_DIF_1)/1200,MESES-OF_ANIOS_INI_1*12,-IF(OF_ANIOS_INI_1=0,CAPITAL,INDEX(CMES_PEND_1,MIN(MESES,OF_ANIOS_INI_1*12)))))) | E11: =IF(NOT(BANCO_OK_2),"",IF(OF_TIPO_2="Fija",CUOTA1_2,PMT(MAX(0,B11+OF_DIF_2)/1200,MESES-OF_ANIOS_INI_2*12,-IF(OF_ANIOS_INI_2=0,CAPITAL,INDEX(CMES_PEND_2,MIN(MESES,OF_ANIOS_INI_2*12)))))) | F11: =IF(NOT(BANCO_OK_3),"",IF(OF_TIPO_3="Fija",CUOTA1_3,PMT(MAX(0,B11+OF_DIF_3)/1200,MESES-OF_ANIOS_INI_3*12,-IF(OF_ANIOS_INI_3=0,CAPITAL,INDEX(CMES_PEND_3,MIN(MESES,OF_ANIOS_INI_3*12)))))) | G11: =IF(NOT(BANCO_OK_4),"",IF(OF_TIPO_4="Fija",CUOTA1_4,PMT(MAX(0,B11+OF_DIF_4)/1200,MESES-OF_ANIOS_INI_4*12,-IF(OF_ANIOS_INI_4=0,CAPITAL,INDEX(CMES_PEND_4,MIN(MESES,OF_ANIOS_INI_4*12))))))
B12: =EURIBOR_HOY+C12 | C12: 2 | D12: =IF(NOT(BANCO_OK_1),"",IF(OF_TIPO_1="Fija",CUOTA1_1,PMT(MAX(0,B12+OF_DIF_1)/1200,MESES-OF_ANIOS_INI_1*12,-IF(OF_ANIOS_INI_1=0,CAPITAL,INDEX(CMES_PEND_1,MIN(MESES,OF_ANIOS_INI_1*12)))))) | E12: =IF(NOT(BANCO_OK_2),"",IF(OF_TIPO_2="Fija",CUOTA1_2,PMT(MAX(0,B12+OF_DIF_2)/1200,MESES-OF_ANIOS_INI_2*12,-IF(OF_ANIOS_INI_2=0,CAPITAL,INDEX(CMES_PEND_2,MIN(MESES,OF_ANIOS_INI_2*12)))))) | F12: =IF(NOT(BANCO_OK_3),"",IF(OF_TIPO_3="Fija",CUOTA1_3,PMT(MAX(0,B12+OF_DIF_3)/1200,MESES-OF_ANIOS_INI_3*12,-IF(OF_ANIOS_INI_3=0,CAPITAL,INDEX(CMES_PEND_3,MIN(MESES,OF_ANIOS_INI_3*12)))))) | G12: =IF(NOT(BANCO_OK_4),"",IF(OF_TIPO_4="Fija",CUOTA1_4,PMT(MAX(0,B12+OF_DIF_4)/1200,MESES-OF_ANIOS_INI_4*12,-IF(OF_ANIOS_INI_4=0,CAPITAL,INDEX(CMES_PEND_4,MIN(MESES,OF_ANIOS_INI_4*12))))))
B13: =EURIBOR_HOY+C13 | C13: 3 | D13: =IF(NOT(BANCO_OK_1),"",IF(OF_TIPO_1="Fija",CUOTA1_1,PMT(MAX(0,B13+OF_DIF_1)/1200,MESES-OF_ANIOS_INI_1*12,-IF(OF_ANIOS_INI_1=0,CAPITAL,INDEX(CMES_PEND_1,MIN(MESES,OF_ANIOS_INI_1*12)))))) | E13: =IF(NOT(BANCO_OK_2),"",IF(OF_TIPO_2="Fija",CUOTA1_2,PMT(MAX(0,B13+OF_DIF_2)/1200,MESES-OF_ANIOS_INI_2*12,-IF(OF_ANIOS_INI_2=0,CAPITAL,INDEX(CMES_PEND_2,MIN(MESES,OF_ANIOS_INI_2*12)))))) | F13: =IF(NOT(BANCO_OK_3),"",IF(OF_TIPO_3="Fija",CUOTA1_3,PMT(MAX(0,B13+OF_DIF_3)/1200,MESES-OF_ANIOS_INI_3*12,-IF(OF_ANIOS_INI_3=0,CAPITAL,INDEX(CMES_PEND_3,MIN(MESES,OF_ANIOS_INI_3*12)))))) | G13: =IF(NOT(BANCO_OK_4),"",IF(OF_TIPO_4="Fija",CUOTA1_4,PMT(MAX(0,B13+OF_DIF_4)/1200,MESES-OF_ANIOS_INI_4*12,-IF(OF_ANIOS_INI_4=0,CAPITAL,INDEX(CMES_PEND_4,MIN(MESES,OF_ANIOS_INI_4*12))))))
B15: Subida de la cuota si el Euríbor sube 2 puntos | D15: =IF(D12="","",D12-D10) | E15: =IF(E12="","",E12-E10) | F15: =IF(F12="","",F12-F10) | G15: =IF(G12="","",G12-G10)
B16: Ingresos netos necesarios con +2 puntos | D16: =IF(D12="","",(D12+VINC_MES_1)/(ESFUERZO/100)) | E16: =IF(E12="","",(E12+VINC_MES_2)/(ESFUERZO/100)) | F16: =IF(F12="","",(F12+VINC_MES_3)/(ESFUERZO/100)) | G16: =IF(G12="","",(G12+VINC_MES_4)/(ESFUERZO/100))
B18: Las fijas no cambian. En las mixtas y variables, la cuota se recalcula cada año con el Euríbor del momento más el diferencial; aquí se supone el mismo Euríbor durante todo el resto del préstamo. Nadie puede predecir el Euríbor: úsalo para ver si podrías pagar en un escenario malo.

Sheet Amortizar antes
B2: Amortizar antes | E2: HogarClaro
B3: Si un día te sobra dinero: ¿reducir cuota o reducir plazo?
B6: ✎ Las celdas amarillas las rellenas tú; el resto se calcula solo.
B8: Oferta (1 a 4) | C8: 1
B9: Amortizas al final del año | C9: 5
B10: Importe que amortizas (€) | C10: 20000
B11: Si es variable o mixta, opción de comisión del contrato | C11: A | D11: A: 0,25 % los 3 primeros años; B: 0,15 % los 5 primeros. Mira tu escritura o la FEIN.
B13: Situación en ese momento
B14: Capital pendiente | C14: =INDEX(CHOOSE(C8,CMES_PEND_1,CMES_PEND_2,CMES_PEND_3,CMES_PEND_4),MIN(MESES,C9*12))
B15: TIN del año siguiente (%) | C15: =INDEX(CHOOSE(C8,CMES_TIN_1,CMES_TIN_2,CMES_TIN_3,CMES_TIN_4),MIN(MESES,MIN(MESES,C9*12)+1))
B16: Meses que quedan | C16: =MESES-MIN(MESES,C9*12)
B17: Tipo de la oferta | C17: =CHOOSE(C8,OF_TIPO_1,OF_TIPO_2,OF_TIPO_3,OF_TIPO_4)
B18: Cuota si no amortizas | C18: =PMT(C15/1200,C16,-C14)
B19: Intereses que te quedan si no amortizas | C19: =C18*C16-C14
B20: Capital pendiente después de amortizar | C20: =MAX(0,C14-C10)
B22: Reducir cuota (mismo plazo)
B23: Cuota nueva | C23: =PMT(C15/1200,C16,-C20)
B24: Intereses que te quedan | C24: =C23*C16-C20
B25: Ahorro de intereses | C25: =C19-C24
B27: Reducir plazo (misma cuota)
B28: Meses que quedan | C28: =IF(C20<=0,0,ROUNDUP(NPER(C15/1200,-C18,C20)-1E-9,0))
B29: Meses que te ahorras | C29: =C16-C28
B30: Intereses que te quedan | C30: =IF(C28=0,0,PMT(C15/1200,C28,-C20)*C28-C20)
B31: Ahorro de intereses | C31: =C19-C30
B33: Comisión
B34: Tope legal de la comisión (%) | C34: =IF(C17="Fija",IF(C9<10,COM_FIJO_10,COM_FIJO_RESTO),IF(C11="B",IF(C9<COM_VAR_B_ANIOS,COM_VAR_B,COM_VAR_DESPUES),IF(C9<COM_VAR_A_ANIOS,COM_VAR_A,COM_VAR_DESPUES)))
B35: Comisión máxima (€) | C35: =MIN(C10,C14)*C34/100 | D35: La ley la limita también a la pérdida financiera real del banco (Ley 5/2019, art. 23): puede ser menor.
B36: Ahorro neto reduciendo plazo (tras la comisión) | C36: =C31-C35
B38: Reducir plazo casi siempre ahorra más intereses; reducir cuota te da más margen cada mes. Calculado con el TIN del año siguiente constante hasta el final. Cálculo orientativo para comparar ofertas: la TAE oficial de la FEIN (Orden EHA/2899/2011) puede diferir unas centésimas. No es asesoramiento financiero.

Sheet Cuadro anual
B2: Cuadro de amortización por años | H2: HogarClaro
B3: ="Oferta: "&CHOOSE(CA_OFERTA,OF_BANCO_1,OF_BANCO_2,OF_BANCO_3,OF_BANCO_4)
B6: Oferta | C6: 1 | D6: Elige 1, 2, 3 o 4
B8: Año | C8: TIN % | D8: Cuota media | E8: Pagado en el año | F8: Intereses | G8: Capital | H8: Pendiente al final
B9: =IF(1*12-11>MESES,"",1) | C9: =IF(B9="","",INDEX(CHOOSE(CA_OFERTA,CMES_TIN_1,CMES_TIN_2,CMES_TIN_3,CMES_TIN_4),1*12-11)) | D9: =IF(B9="","",E9/MIN(12,MESES-(1-1)*12)) | E9: =IF(B9="","",SUMIFS(CHOOSE(CA_OFERTA,CMES_INT_1,CMES_INT_2,CMES_INT_3,CMES_INT_4),CM_ANIO,1)+SUMIFS(CHOOSE(CA_OFERTA,CMES_CAP_1,CMES_CAP_2,CMES_CAP_3,CMES_CAP_4),CM_ANIO,1)) | F9: =IF(B9="","",SUMIFS(CHOOSE(CA_OFERTA,CMES_INT_1,CMES_INT_2,CMES_INT_3,CMES_INT_4),CM_ANIO,1)) | G9: =IF(B9="","",SUMIFS(CHOOSE(CA_OFERTA,CMES_CAP_1,CMES_CAP_2,CMES_CAP_3,CMES_CAP_4),CM_ANIO,1)) | H9: =IF(B9="","",INDEX(CHOOSE(CA_OFERTA,CMES_PEND_1,CMES_PEND_2,CMES_PEND_3,CMES_PEND_4),MIN(MESES,1*12)))
B10: =IF(2*12-11>MESES,"",2) | C10: =IF(B10="","",INDEX(CHOOSE(CA_OFERTA,CMES_TIN_1,CMES_TIN_2,CMES_TIN_3,CMES_TIN_4),2*12-11)) | D10: =IF(B10="","",E10/MIN(12,MESES-(2-1)*12)) | E10: =IF(B10="","",SUMIFS(CHOOSE(CA_OFERTA,CMES_INT_1,CMES_INT_2,CMES_INT_3,CMES_INT_4),CM_ANIO,2)+SUMIFS(CHOOSE(CA_OFERTA,CMES_CAP_1,CMES_CAP_2,CMES_CAP_3,CMES_CAP_4),CM_ANIO,2)) | F10: =IF(B10="","",SUMIFS(CHOOSE(CA_OFERTA,CMES_INT_1,CMES_INT_2,CMES_INT_3,CMES_INT_4),CM_ANIO,2)) | G10: =IF(B10="","",SUMIFS(CHOOSE(CA_OFERTA,CMES_CAP_1,CMES_CAP_2,CMES_CAP_3,CMES_CAP_4),CM_ANIO,2)) | H10: =IF(B10="","",INDEX(CHOOSE(CA_OFERTA,CMES_PEND_1,CMES_PEND_2,CMES_PEND_3,CMES_PEND_4),MIN(MESES,2*12)))
B11: =IF(3*12-11>MESES,"",3) | C11: =IF(B11="","",INDEX(CHOOSE(CA_OFERTA,CMES_TIN_1,CMES_TIN_2,CMES_TIN_3,CMES_TIN_4),3*12-11)) | D11: =IF(B11="","",E11/MIN(12,MESES-(3-1)*12)) | E11: =IF(B11="","",SUMIFS(CHOOSE(CA_OFERTA,CMES_INT_1,CMES_INT_2,CMES_INT_3,CMES_INT_4),CM_ANIO,3)+SUMIFS(CHOOSE(CA_OFERTA,CMES_CAP_1,CMES_CAP_2,CMES_CAP_3,CMES_CAP_4),CM_ANIO,3)) | F11: =IF(B11="","",SUMIFS(CHOOSE(CA_OFERTA,CMES_INT_1,CMES_INT_2,CMES_INT_3,CMES_INT_4),CM_ANIO,3)) | G11: =IF(B11="","",SUMIFS(CHOOSE(CA_OFERTA,CMES_CAP_1,CMES_CAP_2,CMES_CAP_3,CMES_CAP_4),CM_ANIO,3)) | H11: =IF(B11="","",INDEX(CHOOSE(CA_OFERTA,CMES_PEND_1,CMES_PEND_2,CMES_PEND_3,CMES_PEND_4),MIN(MESES,3*12)))
B12: =IF(4*12-11>MESES,"",4) | C12: =IF(B12="","",INDEX(CHOOSE(CA_OFERTA,CMES_TIN_1,CMES_TIN_2,CMES_TIN_3,CMES_TIN_4),4*12-11)) | D12: =IF(B12="","",E12/MIN(12,MESES-(4-1)*12)) | E12: =IF(B12="","",SUMIFS(CHOOSE(CA_OFERTA,CMES_INT_1,CMES_INT_2,CMES_INT_3,CMES_INT_4),CM_ANIO,4)+SUMIFS(CHOOSE(CA_OFERTA,CMES_CAP_1,CMES_CAP_2,CMES_CAP_3,CMES_CAP_4),CM_ANIO,4)) | F12: =IF(B12="","",SUMIFS(CHOOSE(CA_OFERTA,CMES_INT_1,CMES_INT_2,CMES_INT_3,CMES_INT_4),CM_ANIO,4)) | G12: =IF(B12="","",SUMIFS(CHOOSE(CA_OFERTA,CMES_CAP_1,CMES_CAP_2,CMES_CAP_3,CMES_CAP_4),CM_ANIO,4)) | H12: =IF(B12="","",INDEX(CHOOSE(CA_OFERTA,CMES_PEND_1,CMES_PEND_2,CMES_PEND_3,CMES_PEND_4),MIN(MESES,4*12)))
B13: =IF(5*12-11>MESES,"",5) | C13: =IF(B13="","",INDEX(CHOOSE(CA_OFERTA,CMES_TIN_1,CMES_TIN_2,CMES_TIN_3,CMES_TIN_4),5*12-11)) | D13: =IF(B13="","",E13/MIN(12,MESES-(5-1)*12)) | E13: =IF(B13="","",SUMIFS(CHOOSE(CA_OFERTA,CMES_INT_1,CMES_INT_2,CMES_INT_3,CMES_INT_4),CM_ANIO,5)+SUMIFS(CHOOSE(CA_OFERTA,CMES_CAP_1,CMES_CAP_2,CMES_CAP_3,CMES_CAP_4),CM_ANIO,5)) | F13: =IF(B13="","",SUMIFS(CHOOSE(CA_OFERTA,CMES_INT_1,CMES_INT_2,CMES_INT_3,CMES_INT_4),CM_ANIO,5)) | G13: =IF(B13="","",SUMIFS(CHOOSE(CA_OFERTA,CMES_CAP_1,CMES_CAP_2,CMES_CAP_3,CMES_CAP_4),CM_ANIO,5)) | H13: =IF(B13="","",INDEX(CHOOSE(CA_OFERTA,CMES_PEND_1,CMES_PEND_2,CMES_PEND_3,CMES_PEND_4),MIN(MESES,5*12)))
B14: =IF(6*12-11>MESES,"",6) | C14: =IF(B14="","",INDEX(CHOOSE(CA_OFERTA,CMES_TIN_1,CMES_TIN_2,CMES_TIN_3,CMES_TIN_4),6*12-11)) | D14: =IF(B14="","",E14/MIN(12,MESES-(6-1)*12)) | E14: =IF(B14="","",SUMIFS(CHOOSE(CA_OFERTA,CMES_INT_1,CMES_INT_2,CMES_INT_3,CMES_INT_4),CM_ANIO,6)+SUMIFS(CHOOSE(CA_OFERTA,CMES_CAP_1,CMES_CAP_2,CMES_CAP_3,CMES_CAP_4),CM_ANIO,6)) | F14: =IF(B14="","",SUMIFS(CHOOSE(CA_OFERTA,CMES_INT_1,CMES_INT_2,CMES_INT_3,CMES_INT_4),CM_ANIO,6)) | G14: =IF(B14="","",SUMIFS(CHOOSE(CA_OFERTA,CMES_CAP_1,CMES_CAP_2,CMES_CAP_3,CMES_CAP_4),CM_ANIO,6)) | H14: =IF(B14="","",INDEX(CHOOSE(CA_OFERTA,CMES_PEND_1,CMES_PEND_2,CMES_PEND_3,CMES_PEND_4),MIN(MESES,6*12)))
B15: =IF(7*12-11>MESES,"",7) | C15: =IF(B15="","",INDEX(CHOOSE(CA_OFERTA,CMES_TIN_1,CMES_TIN_2,CMES_TIN_3,CMES_TIN_4),7*12-11)) | D15: =IF(B15="","",E15/MIN(12,MESES-(7-1)*12)) | E15: =IF(B15="","",SUMIFS(CHOOSE(CA_OFERTA,CMES_INT_1,CMES_INT_2,CMES_INT_3,CMES_INT_4),CM_ANIO,7)+SUMIFS(CHOOSE(CA_OFERTA,CMES_CAP_1,CMES_CAP_2,CMES_CAP_3,CMES_CAP_4),CM_ANIO,7)) | F15: =IF(B15="","",SUMIFS(CHOOSE(CA_OFERTA,CMES_INT_1,CMES_INT_2,CMES_INT_3,CMES_INT_4),CM_ANIO,7)) | G15: =IF(B15="","",SUMIFS(CHOOSE(CA_OFERTA,CMES_CAP_1,CMES_CAP_2,CMES_CAP_3,CMES_CAP_4),CM_ANIO,7)) | H15: =IF(B15="","",INDEX(CHOOSE(CA_OFERTA,CMES_PEND_1,CMES_PEND_2,CMES_PEND_3,CMES_PEND_4),MIN(MESES,7*12)))
B16: =IF(8*12-11>MESES,"",8) | C16: =IF(B16="","",INDEX(CHOOSE(CA_OFERTA,CMES_TIN_1,CMES_TIN_2,CMES_TIN_3,CMES_TIN_4),8*12-11)) | D16: =IF(B16="","",E16/MIN(12,MESES-(8-1)*12)) | E16: =IF(B16="","",SUMIFS(CHOOSE(CA_OFERTA,CMES_INT_1,CMES_INT_2,CMES_INT_3,CMES_INT_4),CM_ANIO,8)+SUMIFS(CHOOSE(CA_OFERTA,CMES_CAP_1,CMES_CAP_2,CMES_CAP_3,CMES_CAP_4),CM_ANIO,8)) | F16: =IF(B16="","",SUMIFS(CHOOSE(CA_OFERTA,CMES_INT_1,CMES_INT_2,CMES_INT_3,CMES_INT_4),CM_ANIO,8)) | G16: =IF(B16="","",SUMIFS(CHOOSE(CA_OFERTA,CMES_CAP_1,CMES_CAP_2,CMES_CAP_3,CMES_CAP_4),CM_ANIO,8)) | H16: =IF(B16="","",INDEX(CHOOSE(CA_OFERTA,CMES_PEND_1,CMES_PEND_2,CMES_PEND_3,CMES_PEND_4),MIN(MESES,8*12)))
B17: =IF(9*12-11>MESES,"",9) | C17: =IF(B17="","",INDEX(CHOOSE(CA_OFERTA,CMES_TIN_1,CMES_TIN_2,CMES_TIN_3,CMES_TIN_4),9*12-11)) | D17: =IF(B17="","",E17/MIN(12,MESES-(9-1)*12)) | E17: =IF(B17="","",SUMIFS(CHOOSE(CA_OFERTA,CMES_INT_1,CMES_INT_2,CMES_INT_3,CMES_INT_4),CM_ANIO,9)+SUMIFS(CHOOSE(CA_OFERTA,CMES_CAP_1,CMES_CAP_2,CMES_CAP_3,CMES_CAP_4),CM_ANIO,9)) | F17: =IF(B17="","",SUMIFS(CHOOSE(CA_OFERTA,CMES_INT_1,CMES_INT_2,CMES_INT_3,CMES_INT_4),CM_ANIO,9)) | G17: =IF(B17="","",SUMIFS(CHOOSE(CA_OFERTA,CMES_CAP_1,CMES_CAP_2,CMES_CAP_3,CMES_CAP_4),CM_ANIO,9)) | H17: =IF(B17="","",INDEX(CHOOSE(CA_OFERTA,CMES_PEND_1,CMES_PEND_2,CMES_PEND_3,CMES_PEND_4),MIN(MESES,9*12)))
B18: =IF(10*12-11>MESES,"",10) | C18: =IF(B18="","",INDEX(CHOOSE(CA_OFERTA,CMES_TIN_1,CMES_TIN_2,CMES_TIN_3,CMES_TIN_4),10*12-11)) | D18: =IF(B18="","",E18/MIN(12,MESES-(10-1)*12)) | E18: =IF(B18="","",SUMIFS(CHOOSE(CA_OFERTA,CMES_INT_1,CMES_INT_2,CMES_INT_3,CMES_INT_4),CM_ANIO,10)+SUMIFS(CHOOSE(CA_OFERTA,CMES_CAP_1,CMES_CAP_2,CMES_CAP_3,CMES_CAP_4),CM_ANIO,10)) | F18: =IF(B18="","",SUMIFS(CHOOSE(CA_OFERTA,CMES_INT_1,CMES_INT_2,CMES_INT_3,CMES_INT_4),CM_ANIO,10)) | G18: =IF(B18="","",SUMIFS(CHOOSE(CA_OFERTA,CMES_CAP_1,CMES_CAP_2,CMES_CAP_3,CMES_CAP_4),CM_ANIO,10)) | H18: =IF(B18="","",INDEX(CHOOSE(CA_OFERTA,CMES_PEND_1,CMES_PEND_2,CMES_PEND_3,CMES_PEND_4),MIN(MESES,10*12)))
B19: =IF(11*12-11>MESES,"",11) | C19: =IF(B19="","",INDEX(CHOOSE(CA_OFERTA,CMES_TIN_1,CMES_TIN_2,CMES_TIN_3,CMES_TIN_4),11*12-11)) | D19: =IF(B19="","",E19/MIN(12,MESES-(11-1)*12)) | E19: =IF(B19="","",SUMIFS(CHOOSE(CA_OFERTA,CMES_INT_1,CMES_INT_2,CMES_INT_3,CMES_INT_4),CM_ANIO,11)+SUMIFS(CHOOSE(CA_OFERTA,CMES_CAP_1,CMES_CAP_2,CMES_CAP_3,CMES_CAP_4),CM_ANIO,11)) | F19: =IF(B19="","",SUMIFS(CHOOSE(CA_OFERTA,CMES_INT_1,CMES_INT_2,CMES_INT_3,CMES_INT_4),CM_ANIO,11)) | G19: =IF(B19="","",SUMIFS(CHOOSE(CA_OFERTA,CMES_CAP_1,CMES_CAP_2,CMES_CAP_3,CMES_CAP_4),CM_ANIO,11)) | H19: =IF(B19="","",INDEX(CHOOSE(CA_OFERTA,CMES_PEND_1,CMES_PEND_2,CMES_PEND_3,CMES_PEND_4),MIN(MESES,11*12)))
B20: =IF(12*12-11>MESES,"",12) | C20: =IF(B20="","",INDEX(CHOOSE(CA_OFERTA,CMES_TIN_1,CMES_TIN_2,CMES_TIN_3,CMES_TIN_4),12*12-11)) | D20: =IF(B20="","",E20/MIN(12,MESES-(12-1)*12)) | E20: =IF(B20="","",SUMIFS(CHOOSE(CA_OFERTA,CMES_INT_1,CMES_INT_2,CMES_INT_3,CMES_INT_4),CM_ANIO,12)+SUMIFS(CHOOSE(CA_OFERTA,CMES_CAP_1,CMES_CAP_2,CMES_CAP_3,CMES_CAP_4),CM_ANIO,12)) | F20: =IF(B20="","",SUMIFS(CHOOSE(CA_OFERTA,CMES_INT_1,CMES_INT_2,CMES_INT_3,CMES_INT_4),CM_ANIO,12)) | G20: =IF(B20="","",SUMIFS(CHOOSE(CA_OFERTA,CMES_CAP_1,CMES_CAP_2,CMES_CAP_3,CMES_CAP_4),CM_ANIO,12)) | H20: =IF(B20="","",INDEX(CHOOSE(CA_OFERTA,CMES_PEND_1,CMES_PEND_2,CMES_PEND_3,CMES_PEND_4),MIN(MESES,12*12)))
B21: =IF(13*12-11>MESES,"",13) | C21: =IF(B21="","",INDEX(CHOOSE(CA_OFERTA,CMES_TIN_1,CMES_TIN_2,CMES_TIN_3,CMES_TIN_4),13*12-11)) | D21: =IF(B21="","",E21/MIN(12,MESES-(13-1)*12)) | E21: =IF(B21="","",SUMIFS(CHOOSE(CA_OFERTA,CMES_INT_1,CMES_INT_2,CMES_INT_3,CMES_INT_4),CM_ANIO,13)+SUMIFS(CHOOSE(CA_OFERTA,CMES_CAP_1,CMES_CAP_2,CMES_CAP_3,CMES_CAP_4),CM_ANIO,13)) | F21: =IF(B21="","",SUMIFS(CHOOSE(CA_OFERTA,CMES_INT_1,CMES_INT_2,CMES_INT_3,CMES_INT_4),CM_ANIO,13)) | G21: =IF(B21="","",SUMIFS(CHOOSE(CA_OFERTA,CMES_CAP_1,CMES_CAP_2,CMES_CAP_3,CMES_CAP_4),CM_ANIO,13)) | H21: =IF(B21="","",INDEX(CHOOSE(CA_OFERTA,CMES_PEND_1,CMES_PEND_2,CMES_PEND_3,CMES_PEND_4),MIN(MESES,13*12)))
B22: =IF(14*12-11>MESES,"",14) | C22: =IF(B22="","",INDEX(CHOOSE(CA_OFERTA,CMES_TIN_1,CMES_TIN_2,CMES_TIN_3,CMES_TIN_4),14*12-11)) | D22: =IF(B22="","",E22/MIN(12,MESES-(14-1)*12)) | E22: =IF(B22="","",SUMIFS(CHOOSE(CA_OFERTA,CMES_INT_1,CMES_INT_2,CMES_INT_3,CMES_INT_4),CM_ANIO,14)+SUMIFS(CHOOSE(CA_OFERTA,CMES_CAP_1,CMES_CAP_2,CMES_CAP_3,CMES_CAP_4),CM_ANIO,14)) | F22: =IF(B22="","",SUMIFS(CHOOSE(CA_OFERTA,CMES_INT_1,CMES_INT_2,CMES_INT_3,CMES_INT_4),CM_ANIO,14)) | G22: =IF(B22="","",SUMIFS(CHOOSE(CA_OFERTA,CMES_CAP_1,CMES_CAP_2,CMES_CAP_3,CMES_CAP_4),CM_ANIO,14)) | H22: =IF(B22="","",INDEX(CHOOSE(CA_OFERTA,CMES_PEND_1,CMES_PEND_2,CMES_PEND_3,CMES_PEND_4),MIN(MESES,14*12)))
B23: =IF(15*12-11>MESES,"",15) | C23: =IF(B23="","",INDEX(CHOOSE(CA_OFERTA,CMES_TIN_1,CMES_TIN_2,CMES_TIN_3,CMES_TIN_4),15*12-11)) | D23: =IF(B23="","",E23/MIN(12,MESES-(15-1)*12)) | E23: =IF(B23="","",SUMIFS(CHOOSE(CA_OFERTA,CMES_INT_1,CMES_INT_2,CMES_INT_3,CMES_INT_4),CM_ANIO,15)+SUMIFS(CHOOSE(CA_OFERTA,CMES_CAP_1,CMES_CAP_2,CMES_CAP_3,CMES_CAP_4),CM_ANIO,15)) | F23: =IF(B23="","",SUMIFS(CHOOSE(CA_OFERTA,CMES_INT_1,CMES_INT_2,CMES_INT_3,CMES_INT_4),CM_ANIO,15)) | G23: =IF(B23="","",SUMIFS(CHOOSE(CA_OFERTA,CMES_CAP_1,CMES_CAP_2,CMES_CAP_3,CMES_CAP_4),CM_ANIO,15)) | H23: =IF(B23="","",INDEX(CHOOSE(CA_OFERTA,CMES_PEND_1,CMES_PEND_2,CMES_PEND_3,CMES_PEND_4),MIN(MESES,15*12)))
B24: =IF(16*12-11>MESES,"",16) | C24: =IF(B24="","",INDEX(CHOOSE(CA_OFERTA,CMES_TIN_1,CMES_TIN_2,CMES_TIN_3,CMES_TIN_4),16*12-11)) | D24: =IF(B24="","",E24/MIN(12,MESES-(16-1)*12)) | E24: =IF(B24="","",SUMIFS(CHOOSE(CA_OFERTA,CMES_INT_1,CMES_INT_2,CMES_INT_3,CMES_INT_4),CM_ANIO,16)+SUMIFS(CHOOSE(CA_OFERTA,CMES_CAP_1,CMES_CAP_2,CMES_CAP_3,CMES_CAP_4),CM_ANIO,16)) | F24: =IF(B24="","",SUMIFS(CHOOSE(CA_OFERTA,CMES_INT_1,CMES_INT_2,CMES_INT_3,CMES_INT_4),CM_ANIO,16)) | G24: =IF(B24="","",SUMIFS(CHOOSE(CA_OFERTA,CMES_CAP_1,CMES_CAP_2,CMES_CAP_3,CMES_CAP_4),CM_ANIO,16)) | H24: =IF(B24="","",INDEX(CHOOSE(CA_OFERTA,CMES_PEND_1,CMES_PEND_2,CMES_PEND_3,CMES_PEND_4),MIN(MESES,16*12)))
B25: =IF(17*12-11>MESES,"",17) | C25: =IF(B25="","",INDEX(CHOOSE(CA_OFERTA,CMES_TIN_1,CMES_TIN_2,CMES_TIN_3,CMES_TIN_4),17*12-11)) | D25: =IF(B25="","",E25/MIN(12,MESES-(17-1)*12)) | E25: =IF(B25="","",SUMIFS(CHOOSE(CA_OFERTA,CMES_INT_1,CMES_INT_2,CMES_INT_3,CMES_INT_4),CM_ANIO,17)+SUMIFS(CHOOSE(CA_OFERTA,CMES_CAP_1,CMES_CAP_2,CMES_CAP_3,CMES_CAP_4),CM_ANIO,17)) | F25: =IF(B25="","",SUMIFS(CHOOSE(CA_OFERTA,CMES_INT_1,CMES_INT_2,CMES_INT_3,CMES_INT_4),CM_ANIO,17)) | G25: =IF(B25="","",SUMIFS(CHOOSE(CA_OFERTA,CMES_CAP_1,CMES_CAP_2,CMES_CAP_3,CMES_CAP_4),CM_ANIO,17)) | H25: =IF(B25="","",INDEX(CHOOSE(CA_OFERTA,CMES_PEND_1,CMES_PEND_2,CMES_PEND_3,CMES_PEND_4),MIN(MESES,17*12)))
B26: =IF(18*12-11>MESES,"",18) | C26: =IF(B26="","",INDEX(CHOOSE(CA_OFERTA,CMES_TIN_1,CMES_TIN_2,CMES_TIN_3,CMES_TIN_4),18*12-11)) | D26: =IF(B26="","",E26/MIN(12,MESES-(18-1)*12)) | E26: =IF(B26="","",SUMIFS(CHOOSE(CA_OFERTA,CMES_INT_1,CMES_INT_2,CMES_INT_3,CMES_INT_4),CM_ANIO,18)+SUMIFS(CHOOSE(CA_OFERTA,CMES_CAP_1,CMES_CAP_2,CMES_CAP_3,CMES_CAP_4),CM_ANIO,18)) | F26: =IF(B26="","",SUMIFS(CHOOSE(CA_OFERTA,CMES_INT_1,CMES_INT_2,CMES_INT_3,CMES_INT_4),CM_ANIO,18)) | G26: =IF(B26="","",SUMIFS(CHOOSE(CA_OFERTA,CMES_CAP_1,CMES_CAP_2,CMES_CAP_3,CMES_CAP_4),CM_ANIO,18)) | H26: =IF(B26="","",INDEX(CHOOSE(CA_OFERTA,CMES_PEND_1,CMES_PEND_2,CMES_PEND_3,CMES_PEND_4),MIN(MESES,18*12)))
B27: =IF(19*12-11>MESES,"",19) | C27: =IF(B27="","",INDEX(CHOOSE(CA_OFERTA,CMES_TIN_1,CMES_TIN_2,CMES_TIN_3,CMES_TIN_4),19*12-11)) | D27: =IF(B27="","",E27/MIN(12,MESES-(19-1)*12)) | E27: =IF(B27="","",SUMIFS(CHOOSE(CA_OFERTA,CMES_INT_1,CMES_INT_2,CMES_INT_3,CMES_INT_4),CM_ANIO,19)+SUMIFS(CHOOSE(CA_OFERTA,CMES_CAP_1,CMES_CAP_2,CMES_CAP_3,CMES_CAP_4),CM_ANIO,19)) | F27: =IF(B27="","",SUMIFS(CHOOSE(CA_OFERTA,CMES_INT_1,CMES_INT_2,CMES_INT_3,CMES_INT_4),CM_ANIO,19)) | G27: =IF(B27="","",SUMIFS(CHOOSE(CA_OFERTA,CMES_CAP_1,CMES_CAP_2,CMES_CAP_3,CMES_CAP_4),CM_ANIO,19)) | H27: =IF(B27="","",INDEX(CHOOSE(CA_OFERTA,CMES_PEND_1,CMES_PEND_2,CMES_PEND_3,CMES_PEND_4),MIN(MESES,19*12)))
B28: =IF(20*12-11>MESES,"",20) | C28: =IF(B28="","",INDEX(CHOOSE(CA_OFERTA,CMES_TIN_1,CMES_TIN_2,CMES_TIN_3,CMES_TIN_4),20*12-11)) | D28: =IF(B28="","",E28/MIN(12,MESES-(20-1)*12)) | E28: =IF(B28="","",SUMIFS(CHOOSE(CA_OFERTA,CMES_INT_1,CMES_INT_2,CMES_INT_3,CMES_INT_4),CM_ANIO,20)+SUMIFS(CHOOSE(CA_OFERTA,CMES_CAP_1,CMES_CAP_2,CMES_CAP_3,CMES_CAP_4),CM_ANIO,20)) | F28: =IF(B28="","",SUMIFS(CHOOSE(CA_OFERTA,CMES_INT_1,CMES_INT_2,CMES_INT_3,CMES_INT_4),CM_ANIO,20)) | G28: =IF(B28="","",SUMIFS(CHOOSE(CA_OFERTA,CMES_CAP_1,CMES_CAP_2,CMES_CAP_3,CMES_CAP_4),CM_ANIO,20)) | H28: =IF(B28="","",INDEX(CHOOSE(CA_OFERTA,CMES_PEND_1,CMES_PEND_2,CMES_PEND_3,CMES_PEND_4),MIN(MESES,20*12)))
B29: =IF(21*12-11>MESES,"",21) | C29: =IF(B29="","",INDEX(CHOOSE(CA_OFERTA,CMES_TIN_1,CMES_TIN_2,CMES_TIN_3,CMES_TIN_4),21*12-11)) | D29: =IF(B29="","",E29/MIN(12,MESES-(21-1)*12)) | E29: =IF(B29="","",SUMIFS(CHOOSE(CA_OFERTA,CMES_INT_1,CMES_INT_2,CMES_INT_3,CMES_INT_4),CM_ANIO,21)+SUMIFS(CHOOSE(CA_OFERTA,CMES_CAP_1,CMES_CAP_2,CMES_CAP_3,CMES_CAP_4),CM_ANIO,21)) | F29: =IF(B29="","",SUMIFS(CHOOSE(CA_OFERTA,CMES_INT_1,CMES_INT_2,CMES_INT_3,CMES_INT_4),CM_ANIO,21)) | G29: =IF(B29="","",SUMIFS(CHOOSE(CA_OFERTA,CMES_CAP_1,CMES_CAP_2,CMES_CAP_3,CMES_CAP_4),CM_ANIO,21)) | H29: =IF(B29="","",INDEX(CHOOSE(CA_OFERTA,CMES_PEND_1,CMES_PEND_2,CMES_PEND_3,CMES_PEND_4),MIN(MESES,21*12)))
B30: =IF(22*12-11>MESES,"",22) | C30: =IF(B30="","",INDEX(CHOOSE(CA_OFERTA,CMES_TIN_1,CMES_TIN_2,CMES_TIN_3,CMES_TIN_4),22*12-11)) | D30: =IF(B30="","",E30/MIN(12,MESES-(22-1)*12)) | E30: =IF(B30="","",SUMIFS(CHOOSE(CA_OFERTA,CMES_INT_1,CMES_INT_2,CMES_INT_3,CMES_INT_4),CM_ANIO,22)+SUMIFS(CHOOSE(CA_OFERTA,CMES_CAP_1,CMES_CAP_2,CMES_CAP_3,CMES_CAP_4),CM_ANIO,22)) | F30: =IF(B30="","",SUMIFS(CHOOSE(CA_OFERTA,CMES_INT_1,CMES_INT_2,CMES_INT_3,CMES_INT_4),CM_ANIO,22)) | G30: =IF(B30="","",SUMIFS(CHOOSE(CA_OFERTA,CMES_CAP_1,CMES_CAP_2,CMES_CAP_3,CMES_CAP_4),CM_ANIO,22)) | H30: =IF(B30="","",INDEX(CHOOSE(CA_OFERTA,CMES_PEND_1,CMES_PEND_2,CMES_PEND_3,CMES_PEND_4),MIN(MESES,22*12)))
B31: =IF(23*12-11>MESES,"",23) | C31: =IF(B31="","",INDEX(CHOOSE(CA_OFERTA,CMES_TIN_1,CMES_TIN_2,CMES_TIN_3,CMES_TIN_4),23*12-11)) | D31: =IF(B31="","",E31/MIN(12,MESES-(23-1)*12)) | E31: =IF(B31="","",SUMIFS(CHOOSE(CA_OFERTA,CMES_INT_1,CMES_INT_2,CMES_INT_3,CMES_INT_4),CM_ANIO,23)+SUMIFS(CHOOSE(CA_OFERTA,CMES_CAP_1,CMES_CAP_2,CMES_CAP_3,CMES_CAP_4),CM_ANIO,23)) | F31: =IF(B31="","",SUMIFS(CHOOSE(CA_OFERTA,CMES_INT_1,CMES_INT_2,CMES_INT_3,CMES_INT_4),CM_ANIO,23)) | G31: =IF(B31="","",SUMIFS(CHOOSE(CA_OFERTA,CMES_CAP_1,CMES_CAP_2,CMES_CAP_3,CMES_CAP_4),CM_ANIO,23)) | H31: =IF(B31="","",INDEX(CHOOSE(CA_OFERTA,CMES_PEND_1,CMES_PEND_2,CMES_PEND_3,CMES_PEND_4),MIN(MESES,23*12)))
B32: =IF(24*12-11>MESES,"",24) | C32: =IF(B32="","",INDEX(CHOOSE(CA_OFERTA,CMES_TIN_1,CMES_TIN_2,CMES_TIN_3,CMES_TIN_4),24*12-11)) | D32: =IF(B32="","",E32/MIN(12,MESES-(24-1)*12)) | E32: =IF(B32="","",SUMIFS(CHOOSE(CA_OFERTA,CMES_INT_1,CMES_INT_2,CMES_INT_3,CMES_INT_4),CM_ANIO,24)+SUMIFS(CHOOSE(CA_OFERTA,CMES_CAP_1,CMES_CAP_2,CMES_CAP_3,CMES_CAP_4),CM_ANIO,24)) | F32: =IF(B32="","",SUMIFS(CHOOSE(CA_OFERTA,CMES_INT_1,CMES_INT_2,CMES_INT_3,CMES_INT_4),CM_ANIO,24)) | G32: =IF(B32="","",SUMIFS(CHOOSE(CA_OFERTA,CMES_CAP_1,CMES_CAP_2,CMES_CAP_3,CMES_CAP_4),CM_ANIO,24)) | H32: =IF(B32="","",INDEX(CHOOSE(CA_OFERTA,CMES_PEND_1,CMES_PEND_2,CMES_PEND_3,CMES_PEND_4),MIN(MESES,24*12)))
B33: =IF(25*12-11>MESES,"",25) | C33: =IF(B33="","",INDEX(CHOOSE(CA_OFERTA,CMES_TIN_1,CMES_TIN_2,CMES_TIN_3,CMES_TIN_4),25*12-11)) | D33: =IF(B33="","",E33/MIN(12,MESES-(25-1)*12)) | E33: =IF(B33="","",SUMIFS(CHOOSE(CA_OFERTA,CMES_INT_1,CMES_INT_2,CMES_INT_3,CMES_INT_4),CM_ANIO,25)+SUMIFS(CHOOSE(CA_OFERTA,CMES_CAP_1,CMES_CAP_2,CMES_CAP_3,CMES_CAP_4),CM_ANIO,25)) | F33: =IF(B33="","",SUMIFS(CHOOSE(CA_OFERTA,CMES_INT_1,CMES_INT_2,CMES_INT_3,CMES_INT_4),CM_ANIO,25)) | G33: =IF(B33="","",SUMIFS(CHOOSE(CA_OFERTA,CMES_CAP_1,CMES_CAP_2,CMES_CAP_3,CMES_CAP_4),CM_ANIO,25)) | H33: =IF(B33="","",INDEX(CHOOSE(CA_OFERTA,CMES_PEND_1,CMES_PEND_2,CMES_PEND_3,CMES_PEND_4),MIN(MESES,25*12)))
B34: =IF(26*12-11>MESES,"",26) | C34: =IF(B34="","",INDEX(CHOOSE(CA_OFERTA,CMES_TIN_1,CMES_TIN_2,CMES_TIN_3,CMES_TIN_4),26*12-11)) | D34: =IF(B34="","",E34/MIN(12,MESES-(26-1)*12)) | E34: =IF(B34="","",SUMIFS(CHOOSE(CA_OFERTA,CMES_INT_1,CMES_INT_2,CMES_INT_3,CMES_INT_4),CM_ANIO,26)+SUMIFS(CHOOSE(CA_OFERTA,CMES_CAP_1,CMES_CAP_2,CMES_CAP_3,CMES_CAP_4),CM_ANIO,26)) | F34: =IF(B34="","",SUMIFS(CHOOSE(CA_OFERTA,CMES_INT_1,CMES_INT_2,CMES_INT_3,CMES_INT_4),CM_ANIO,26)) | G34: =IF(B34="","",SUMIFS(CHOOSE(CA_OFERTA,CMES_CAP_1,CMES_CAP_2,CMES_CAP_3,CMES_CAP_4),CM_ANIO,26)) | H34: =IF(B34="","",INDEX(CHOOSE(CA_OFERTA,CMES_PEND_1,CMES_PEND_2,CMES_PEND_3,CMES_PEND_4),MIN(MESES,26*12)))
B35: =IF(27*12-11>MESES,"",27) | C35: =IF(B35="","",INDEX(CHOOSE(CA_OFERTA,CMES_TIN_1,CMES_TIN_2,CMES_TIN_3,CMES_TIN_4),27*12-11)) | D35: =IF(B35="","",E35/MIN(12,MESES-(27-1)*12)) | E35: =IF(B35="","",SUMIFS(CHOOSE(CA_OFERTA,CMES_INT_1,CMES_INT_2,CMES_INT_3,CMES_INT_4),CM_ANIO,27)+SUMIFS(CHOOSE(CA_OFERTA,CMES_CAP_1,CMES_CAP_2,CMES_CAP_3,CMES_CAP_4),CM_ANIO,27)) | F35: =IF(B35="","",SUMIFS(CHOOSE(CA_OFERTA,CMES_INT_1,CMES_INT_2,CMES_INT_3,CMES_INT_4),CM_ANIO,27)) | G35: =IF(B35="","",SUMIFS(CHOOSE(CA_OFERTA,CMES_CAP_1,CMES_CAP_2,CMES_CAP_3,CMES_CAP_4),CM_ANIO,27)) | H35: =IF(B35="","",INDEX(CHOOSE(CA_OFERTA,CMES_PEND_1,CMES_PEND_2,CMES_PEND_3,CMES_PEND_4),MIN(MESES,27*12)))
B36: =IF(28*12-11>MESES,"",28) | C36: =IF(B36="","",INDEX(CHOOSE(CA_OFERTA,CMES_TIN_1,CMES_TIN_2,CMES_TIN_3,CMES_TIN_4),28*12-11)) | D36: =IF(B36="","",E36/MIN(12,MESES-(28-1)*12)) | E36: =IF(B36="","",SUMIFS(CHOOSE(CA_OFERTA,CMES_INT_1,CMES_INT_2,CMES_INT_3,CMES_INT_4),CM_ANIO,28)+SUMIFS(CHOOSE(CA_OFERTA,CMES_CAP_1,CMES_CAP_2,CMES_CAP_3,CMES_CAP_4),CM_ANIO,28)) | F36: =IF(B36="","",SUMIFS(CHOOSE(CA_OFERTA,CMES_INT_1,CMES_INT_2,CMES_INT_3,CMES_INT_4),CM_ANIO,28)) | G36: =IF(B36="","",SUMIFS(CHOOSE(CA_OFERTA,CMES_CAP_1,CMES_CAP_2,CMES_CAP_3,CMES_CAP_4),CM_ANIO,28)) | H36: =IF(B36="","",INDEX(CHOOSE(CA_OFERTA,CMES_PEND_1,CMES_PEND_2,CMES_PEND_3,CMES_PEND_4),MIN(MESES,28*12)))
B37: =IF(29*12-11>MESES,"",29) | C37: =IF(B37="","",INDEX(CHOOSE(CA_OFERTA,CMES_TIN_1,CMES_TIN_2,CMES_TIN_3,CMES_TIN_4),29*12-11)) | D37: =IF(B37="","",E37/MIN(12,MESES-(29-1)*12)) | E37: =IF(B37="","",SUMIFS(CHOOSE(CA_OFERTA,CMES_INT_1,CMES_INT_2,CMES_INT_3,CMES_INT_4),CM_ANIO,29)+SUMIFS(CHOOSE(CA_OFERTA,CMES_CAP_1,CMES_CAP_2,CMES_CAP_3,CMES_CAP_4),CM_ANIO,29)) | F37: =IF(B37="","",SUMIFS(CHOOSE(CA_OFERTA,CMES_INT_1,CMES_INT_2,CMES_INT_3,CMES_INT_4),CM_ANIO,29)) | G37: =IF(B37="","",SUMIFS(CHOOSE(CA_OFERTA,CMES_CAP_1,CMES_CAP_2,CMES_CAP_3,CMES_CAP_4),CM_ANIO,29)) | H37: =IF(B37="","",INDEX(CHOOSE(CA_OFERTA,CMES_PEND_1,CMES_PEND_2,CMES_PEND_3,CMES_PEND_4),MIN(MESES,29*12)))
B38: =IF(30*12-11>MESES,"",30) | C38: =IF(B38="","",INDEX(CHOOSE(CA_OFERTA,CMES_TIN_1,CMES_TIN_2,CMES_TIN_3,CMES_TIN_4),30*12-11)) | D38: =IF(B38="","",E38/MIN(12,MESES-(30-1)*12)) | E38: =IF(B38="","",SUMIFS(CHOOSE(CA_OFERTA,CMES_INT_1,CMES_INT_2,CMES_INT_3,CMES_INT_4),CM_ANIO,30)+SUMIFS(CHOOSE(CA_OFERTA,CMES_CAP_1,CMES_CAP_2,CMES_CAP_3,CMES_CAP_4),CM_ANIO,30)) | F38: =IF(B38="","",SUMIFS(CHOOSE(CA_OFERTA,CMES_INT_1,CMES_INT_2,CMES_INT_3,CMES_INT_4),CM_ANIO,30)) | G38: =IF(B38="","",SUMIFS(CHOOSE(CA_OFERTA,CMES_CAP_1,CMES_CAP_2,CMES_CAP_3,CMES_CAP_4),CM_ANIO,30)) | H38: =IF(B38="","",INDEX(CHOOSE(CA_OFERTA,CMES_PEND_1,CMES_PEND_2,CMES_PEND_3,CMES_PEND_4),MIN(MESES,30*12)))
B39: =IF(31*12-11>MESES,"",31) | C39: =IF(B39="","",INDEX(CHOOSE(CA_OFERTA,CMES_TIN_1,CMES_TIN_2,CMES_TIN_3,CMES_TIN_4),31*12-11)) | D39: =IF(B39="","",E39/MIN(12,MESES-(31-1)*12)) | E39: =IF(B39="","",SUMIFS(CHOOSE(CA_OFERTA,CMES_INT_1,CMES_INT_2,CMES_INT_3,CMES_INT_4),CM_ANIO,31)+SUMIFS(CHOOSE(CA_OFERTA,CMES_CAP_1,CMES_CAP_2,CMES_CAP_3,CMES_CAP_4),CM_ANIO,31)) | F39: =IF(B39="","",SUMIFS(CHOOSE(CA_OFERTA,CMES_INT_1,CMES_INT_2,CMES_INT_3,CMES_INT_4),CM_ANIO,31)) | G39: =IF(B39="","",SUMIFS(CHOOSE(CA_OFERTA,CMES_CAP_1,CMES_CAP_2,CMES_CAP_3,CMES_CAP_4),CM_ANIO,31)) | H39: =IF(B39="","",INDEX(CHOOSE(CA_OFERTA,CMES_PEND_1,CMES_PEND_2,CMES_PEND_3,CMES_PEND_4),MIN(MESES,31*12)))
B40: =IF(32*12-11>MESES,"",32) | C40: =IF(B40="","",INDEX(CHOOSE(CA_OFERTA,CMES_TIN_1,CMES_TIN_2,CMES_TIN_3,CMES_TIN_4),32*12-11)) | D40: =IF(B40="","",E40/MIN(12,MESES-(32-1)*12)) | E40: =IF(B40="","",SUMIFS(CHOOSE(CA_OFERTA,CMES_INT_1,CMES_INT_2,CMES_INT_3,CMES_INT_4),CM_ANIO,32)+SUMIFS(CHOOSE(CA_OFERTA,CMES_CAP_1,CMES_CAP_2,CMES_CAP_3,CMES_CAP_4),CM_ANIO,32)) | F40: =IF(B40="","",SUMIFS(CHOOSE(CA_OFERTA,CMES_INT_1,CMES_INT_2,CMES_INT_3,CMES_INT_4),CM_ANIO,32)) | G40: =IF(B40="","",SUMIFS(CHOOSE(CA_OFERTA,CMES_CAP_1,CMES_CAP_2,CMES_CAP_3,CMES_CAP_4),CM_ANIO,32)) | H40: =IF(B40="","",INDEX(CHOOSE(CA_OFERTA,CMES_PEND_1,CMES_PEND_2,CMES_PEND_3,CMES_PEND_4),MIN(MESES,32*12)))
B41: =IF(33*12-11>MESES,"",33) | C41: =IF(B41="","",INDEX(CHOOSE(CA_OFERTA,CMES_TIN_1,CMES_TIN_2,CMES_TIN_3,CMES_TIN_4),33*12-11)) | D41: =IF(B41="","",E41/MIN(12,MESES-(33-1)*12)) | E41: =IF(B41="","",SUMIFS(CHOOSE(CA_OFERTA,CMES_INT_1,CMES_INT_2,CMES_INT_3,CMES_INT_4),CM_ANIO,33)+SUMIFS(CHOOSE(CA_OFERTA,CMES_CAP_1,CMES_CAP_2,CMES_CAP_3,CMES_CAP_4),CM_ANIO,33)) | F41: =IF(B41="","",SUMIFS(CHOOSE(CA_OFERTA,CMES_INT_1,CMES_INT_2,CMES_INT_3,CMES_INT_4),CM_ANIO,33)) | G41: =IF(B41="","",SUMIFS(CHOOSE(CA_OFERTA,CMES_CAP_1,CMES_CAP_2,CMES_CAP_3,CMES_CAP_4),CM_ANIO,33)) | H41: =IF(B41="","",INDEX(CHOOSE(CA_OFERTA,CMES_PEND_1,CMES_PEND_2,CMES_PEND_3,CMES_PEND_4),MIN(MESES,33*12)))
B42: =IF(34*12-11>MESES,"",34) | C42: =IF(B42="","",INDEX(CHOOSE(CA_OFERTA,CMES_TIN_1,CMES_TIN_2,CMES_TIN_3,CMES_TIN_4),34*12-11)) | D42: =IF(B42="","",E42/MIN(12,MESES-(34-1)*12)) | E42: =IF(B42="","",SUMIFS(CHOOSE(CA_OFERTA,CMES_INT_1,CMES_INT_2,CMES_INT_3,CMES_INT_4),CM_ANIO,34)+SUMIFS(CHOOSE(CA_OFERTA,CMES_CAP_1,CMES_CAP_2,CMES_CAP_3,CMES_CAP_4),CM_ANIO,34)) | F42: =IF(B42="","",SUMIFS(CHOOSE(CA_OFERTA,CMES_INT_1,CMES_INT_2,CMES_INT_3,CMES_INT_4),CM_ANIO,34)) | G42: =IF(B42="","",SUMIFS(CHOOSE(CA_OFERTA,CMES_CAP_1,CMES_CAP_2,CMES_CAP_3,CMES_CAP_4),CM_ANIO,34)) | H42: =IF(B42="","",INDEX(CHOOSE(CA_OFERTA,CMES_PEND_1,CMES_PEND_2,CMES_PEND_3,CMES_PEND_4),MIN(MESES,34*12)))
B43: =IF(35*12-11>MESES,"",35) | C43: =IF(B43="","",INDEX(CHOOSE(CA_OFERTA,CMES_TIN_1,CMES_TIN_2,CMES_TIN_3,CMES_TIN_4),35*12-11)) | D43: =IF(B43="","",E43/MIN(12,MESES-(35-1)*12)) | E43: =IF(B43="","",SUMIFS(CHOOSE(CA_OFERTA,CMES_INT_1,CMES_INT_2,CMES_INT_3,CMES_INT_4),CM_ANIO,35)+SUMIFS(CHOOSE(CA_OFERTA,CMES_CAP_1,CMES_CAP_2,CMES_CAP_3,CMES_CAP_4),CM_ANIO,35)) | F43: =IF(B43="","",SUMIFS(CHOOSE(CA_OFERTA,CMES_INT_1,CMES_INT_2,CMES_INT_3,CMES_INT_4),CM_ANIO,35)) | G43: =IF(B43="","",SUMIFS(CHOOSE(CA_OFERTA,CMES_CAP_1,CMES_CAP_2,CMES_CAP_3,CMES_CAP_4),CM_ANIO,35)) | H43: =IF(B43="","",INDEX(CHOOSE(CA_OFERTA,CMES_PEND_1,CMES_PEND_2,CMES_PEND_3,CMES_PEND_4),MIN(MESES,35*12)))
B44: =IF(36*12-11>MESES,"",36) | C44: =IF(B44="","",INDEX(CHOOSE(CA_OFERTA,CMES_TIN_1,CMES_TIN_2,CMES_TIN_3,CMES_TIN_4),36*12-11)) | D44: =IF(B44="","",E44/MIN(12,MESES-(36-1)*12)) | E44: =IF(B44="","",SUMIFS(CHOOSE(CA_OFERTA,CMES_INT_1,CMES_INT_2,CMES_INT_3,CMES_INT_4),CM_ANIO,36)+SUMIFS(CHOOSE(CA_OFERTA,CMES_CAP_1,CMES_CAP_2,CMES_CAP_3,CMES_CAP_4),CM_ANIO,36)) | F44: =IF(B44="","",SUMIFS(CHOOSE(CA_OFERTA,CMES_INT_1,CMES_INT_2,CMES_INT_3,CMES_INT_4),CM_ANIO,36)) | G44: =IF(B44="","",SUMIFS(CHOOSE(CA_OFERTA,CMES_CAP_1,CMES_CAP_2,CMES_CAP_3,CMES_CAP_4),CM_ANIO,36)) | H44: =IF(B44="","",INDEX(CHOOSE(CA_OFERTA,CMES_PEND_1,CMES_PEND_2,CMES_PEND_3,CMES_PEND_4),MIN(MESES,36*12)))
...

Sheet Cuadro mensual
B2: Cuadro mensual de las cuatro ofertas | AA2: HogarClaro
B3: Sistema francés con revisión anual del tipo. Lo usan las demás hojas: no hace falta tocarlo.
D6: =IF(OF_BANCO_1="","Oferta 1",OF_BANCO_1) | J6: =IF(OF_BANCO_2="","Oferta 2",OF_BANCO_2) | P6: =IF(OF_BANCO_3="","Oferta 3",OF_BANCO_3) | V6: =IF(OF_BANCO_4="","Oferta 4",OF_BANCO_4)
B7: Mes | C7: Año | D7: TIN % | E7: Cuota | F7: Interés | G7: Capital | H7: Pendiente | I7: Flujo (TAE) | J7: TIN % | K7: Cuota | L7: Interés | M7: Capital | N7: Pendiente | O7: Flujo (TAE) | P7: TIN % | Q7: Cuota | R7: Interés | S7: Capital | T7: Pendiente | U7: Flujo (TAE) | V7: TIN % | W7: Cuota | X7: Interés | Y7: Capital | Z7: Pendiente | AA7: Flujo (TAE)
B8: 0 | H8: =IF(BANCO_OK_1,CAPITAL,0) | I8: =IF(BANCO_OK_1,-(CAPITAL-GASTOS_1),0) | N8: =IF(BANCO_OK_2,CAPITAL,0) | O8: =IF(BANCO_OK_2,-(CAPITAL-GASTOS_2),0) | T8: =IF(BANCO_OK_3,CAPITAL,0) | U8: =IF(BANCO_OK_3,-(CAPITAL-GASTOS_3),0) | Z8: =IF(BANCO_OK_4,CAPITAL,0) | AA8: =IF(BANCO_OK_4,-(CAPITAL-GASTOS_4),0)
B9: 1 | C9: =ROUNDUP(B9/12,0) | D9: =IF(AND(BANCO_OK_1,B9<=MESES),IF(OR(OF_TIPO_1="Fija",C9<=OF_ANIOS_INI_1),OF_TIN_1,MAX(0,EURIBOR+OF_DIF_1)),0) | E9: =IF(AND(BANCO_OK_1,B9<=MESES),IF(OR(B9=1,D9<>-1),PMT(D9/1200,MESES-B9+1,-H8),0),0) | F9: =H8*D9/1200 | G9: =IF(AND(BANCO_OK_1,B9<=MESES),IF(OR(B9=MESES,E9-F9>H8),H8,E9-F9),0) | H9: =H8-G9 | I9: =IF(AND(BANCO_OK_1,B9<=MESES),F9+G9+VINC_MES_1,0) | J9: =IF(AND(BANCO_OK_2,B9<=MESES),IF(OR(OF_TIPO_2="Fija",C9<=OF_ANIOS_INI_2),OF_TIN_2,MAX(0,EURIBOR+OF_DIF_2)),0) | K9: =IF(AND(BANCO_OK_2,B9<=MESES),IF(OR(B9=1,J9<>-1),PMT(J9/1200,MESES-B9+1,-N8),0),0) | L9: =N8*J9/1200 | M9: =IF(AND(BANCO_OK_2,B9<=MESES),IF(OR(B9=MESES,K9-L9>N8),N8,K9-L9),0) | N9: =N8-M9 | O9: =IF(AND(BANCO_OK_2,B9<=MESES),L9+M9+VINC_MES_2,0) | P9: =IF(AND(BANCO_OK_3,B9<=MESES),IF(OR(OF_TIPO_3="Fija",C9<=OF_ANIOS_INI_3),OF_TIN_3,MAX(0,EURIBOR+OF_DIF_3)),0) | Q9: =IF(AND(BANCO_OK_3,B9<=MESES),IF(OR(B9=1,P9<>-1),PMT(P9/1200,MESES-B9+1,-T8),0),0) | R9: =T8*P9/1200 | S9: =IF(AND(BANCO_OK_3,B9<=MESES),IF(OR(B9=MESES,Q9-R9>T8),T8,Q9-R9),0) | T9: =T8-S9 | U9: =IF(AND(BANCO_OK_3,B9<=MESES),R9+S9+VINC_MES_3,0) | V9: =IF(AND(BANCO_OK_4,B9<=MESES),IF(OR(OF_TIPO_4="Fija",C9<=OF_ANIOS_INI_4),OF_TIN_4,MAX(0,EURIBOR+OF_DIF_4)),0) | W9: =IF(AND(BANCO_OK_4,B9<=MESES),IF(OR(B9=1,V9<>-1),PMT(V9/1200,MESES-B9+1,-Z8),0),0) | X9: =Z8*V9/1200 | Y9: =IF(AND(BANCO_OK_4,B9<=MESES),IF(OR(B9=MESES,W9-X9>Z8),Z8,W9-X9),0) | Z9: =Z8-Y9 | AA9: =IF(AND(BANCO_OK_4,B9<=MESES),X9+Y9+VINC_MES_4,0)
B10: 2 | C10: =ROUNDUP(B10/12,0) | D10: =IF(AND(BANCO_OK_1,B10<=MESES),IF(OR(OF_TIPO_1="Fija",C10<=OF_ANIOS_INI_1),OF_TIN_1,MAX(0,EURIBOR+OF_DIF_1)),0) | E10: =IF(AND(BANCO_OK_1,B10<=MESES),IF(OR(B10=1,D10<>D9),PMT(D10/1200,MESES-B10+1,-H9),E9),0) | F10: =H9*D10/1200 | G10: =IF(AND(BANCO_OK_1,B10<=MESES),IF(OR(B10=MESES,E10-F10>H9),H9,E10-F10),0) | H10: =H9-G10 | I10: =IF(AND(BANCO_OK_1,B10<=MESES),F10+G10+VINC_MES_1,0) | J10: =IF(AND(BANCO_OK_2,B10<=MESES),IF(OR(OF_TIPO_2="Fija",C10<=OF_ANIOS_INI_2),OF_TIN_2,MAX(0,EURIBOR+OF_DIF_2)),0) | K10: =IF(AND(BANCO_OK_2,B10<=MESES),IF(OR(B10=1,J10<>J9),PMT(J10/1200,MESES-B10+1,-N9),K9),0) | L10: =N9*J10/1200 | M10: =IF(AND(BANCO_OK_2,B10<=MESES),IF(OR(B10=MESES,K10-L10>N9),N9,K10-L10),0) | N10: =N9-M10 | O10: =IF(AND(BANCO_OK_2,B10<=MESES),L10+M10+VINC_MES_2,0) | P10: =IF(AND(BANCO_OK_3,B10<=MESES),IF(OR(OF_TIPO_3="Fija",C10<=OF_ANIOS_INI_3),OF_TIN_3,MAX(0,EURIBOR+OF_DIF_3)),0) | Q10: =IF(AND(BANCO_OK_3,B10<=MESES),IF(OR(B10=1,P10<>P9),PMT(P10/1200,MESES-B10+1,-T9),Q9),0) | R10: =T9*P10/1200 | S10: =IF(AND(BANCO_OK_3,B10<=MESES),IF(OR(B10=MESES,Q10-R10>T9),T9,Q10-R10),0) | T10: =T9-S10 | U10: =IF(AND(BANCO_OK_3,B10<=MESES),R10+S10+VINC_MES_3,0) | V10: =IF(AND(BANCO_OK_4,B10<=MESES),IF(OR(OF_TIPO_4="Fija",C10<=OF_ANIOS_INI_4),OF_TIN_4,MAX(0,EURIBOR+OF_DIF_4)),0) | W10: =IF(AND(BANCO_OK_4,B10<=MESES),IF(OR(B10=1,V10<>V9),PMT(V10/1200,MESES-B10+1,-Z9),W9),0) | X10: =Z9*V10/1200 | Y10: =IF(AND(BANCO_OK_4,B10<=MESES),IF(OR(B10=MESES,W10-X10>Z9),Z9,W10-X10),0) | Z10: =Z9-Y10 | AA10: =IF(AND(BANCO_OK_4,B10<=MESES),X10+Y10+VINC_MES_4,0)
B11: 3 | C11: =ROUNDUP(B11/12,0) | D11: =IF(AND(BANCO_OK_1,B11<=MESES),IF(OR(OF_TIPO_1="Fija",C11<=OF_ANIOS_INI_1),OF_TIN_1,MAX(0,EURIBOR+OF_DIF_1)),0) | E11: =IF(AND(BANCO_OK_1,B11<=MESES),IF(OR(B11=1,D11<>D10),PMT(D11/1200,MESES-B11+1,-H10),E10),0) | F11: =H10*D11/1200 | G11: =IF(AND(BANCO_OK_1,B11<=MESES),IF(OR(B11=MESES,E11-F11>H10),H10,E11-F11),0) | H11: =H10-G11 | I11: =IF(AND(BANCO_OK_1,B11<=MESES),F11+G11+VINC_MES_1,0) | J11: =IF(AND(BANCO_OK_2,B11<=MESES),IF(OR(OF_TIPO_2="Fija",C11<=OF_ANIOS_INI_2),OF_TIN_2,MAX(0,EURIBOR+OF_DIF_2)),0) | K11: =IF(AND(BANCO_OK_2,B11<=MESES),IF(OR(B11=1,J11<>J10),PMT(J11/1200,MESES-B11+1,-N10),K10),0) | L11: =N10*J11/1200 | M11: =IF(AND(BANCO_OK_2,B11<=MESES),IF(OR(B11=MESES,K11-L11>N10),N10,K11-L11),0) | N11: =N10-M11 | O11: =IF(AND(BANCO_OK_2,B11<=MESES),L11+M11+VINC_MES_2,0) | P11: =IF(AND(BANCO_OK_3,B11<=MESES),IF(OR(OF_TIPO_3="Fija",C11<=OF_ANIOS_INI_3),OF_TIN_3,MAX(0,EURIBOR+OF_DIF_3)),0) | Q11: =IF(AND(BANCO_OK_3,B11<=MESES),IF(OR(B11=1,P11<>P10),PMT(P11/1200,MESES-B11+1,-T10),Q10),0) | R11: =T10*P11/1200 | S11: =IF(AND(BANCO_OK_3,B11<=MESES),IF(OR(B11=MESES,Q11-R11>T10),T10,Q11-R11),0) | T11: =T10-S11 | U11: =IF(AND(BANCO_OK_3,B11<=MESES),R11+S11+VINC_MES_3,0) | V11: =IF(AND(BANCO_OK_4,B11<=MESES),IF(OR(OF_TIPO_4="Fija",C11<=OF_ANIOS_INI_4),OF_TIN_4,MAX(0,EURIBOR+OF_DIF_4)),0) | W11: =IF(AND(BANCO_OK_4,B11<=MESES),IF(OR(B11=1,V11<>V10),PMT(V11/1200,MESES-B11+1,-Z10),W10),0) | X11: =Z10*V11/1200 | Y11: =IF(AND(BANCO_OK_4,B11<=MESES),IF(OR(B11=MESES,W11-X11>Z10),Z10,W11-X11),0) | Z11: =Z10-Y11 | AA11: =IF(AND(BANCO_OK_4,B11<=MESES),X11+Y11+VINC_MES_4,0)
B12: 4 | C12: =ROUNDUP(B12/12,0) | D12: =IF(AND(BANCO_OK_1,B12<=MESES),IF(OR(OF_TIPO_1="Fija",C12<=OF_ANIOS_INI_1),OF_TIN_1,MAX(0,EURIBOR+OF_DIF_1)),0) | E12: =IF(AND(BANCO_OK_1,B12<=MESES),IF(OR(B12=1,D12<>D11),PMT(D12/1200,MESES-B12+1,-H11),E11),0) | F12: =H11*D12/1200 | G12: =IF(AND(BANCO_OK_1,B12<=MESES),IF(OR(B12=MESES,E12-F12>H11),H11,E12-F12),0) | H12: =H11-G12 | I12: =IF(AND(BANCO_OK_1,B12<=MESES),F12+G12+VINC_MES_1,0) | J12: =IF(AND(BANCO_OK_2,B12<=MESES),IF(OR(OF_TIPO_2="Fija",C12<=OF_ANIOS_INI_2),OF_TIN_2,MAX(0,EURIBOR+OF_DIF_2)),0) | K12: =IF(AND(BANCO_OK_2,B12<=MESES),IF(OR(B12=1,J12<>J11),PMT(J12/1200,MESES-B12+1,-N11),K11),0) | L12: =N11*J12/1200 | M12: =IF(AND(BANCO_OK_2,B12<=MESES),IF(OR(B12=MESES,K12-L12>N11),N11,K12-L12),0) | N12: =N11-M12 | O12: =IF(AND(BANCO_OK_2,B12<=MESES),L12+M12+VINC_MES_2,0) | P12: =IF(AND(BANCO_OK_3,B12<=MESES),IF(OR(OF_TIPO_3="Fija",C12<=OF_ANIOS_INI_3),OF_TIN_3,MAX(0,EURIBOR+OF_DIF_3)),0) | Q12: =IF(AND(BANCO_OK_3,B12<=MESES),IF(OR(B12=1,P12<>P11),PMT(P12/1200,MESES-B12+1,-T11),Q11),0) | R12: =T11*P12/1200 | S12: =IF(AND(BANCO_OK_3,B12<=MESES),IF(OR(B12=MESES,Q12-R12>T11),T11,Q12-R12),0) | T12: =T11-S12 | U12: =IF(AND(BANCO_OK_3,B12<=MESES),R12+S12+VINC_MES_3,0) | V12: =IF(AND(BANCO_OK_4,B12<=MESES),IF(OR(OF_TIPO_4="Fija",C12<=OF_ANIOS_INI_4),OF_TIN_4,MAX(0,EURIBOR+OF_DIF_4)),0) | W12: =IF(AND(BANCO_OK_4,B12<=MESES),IF(OR(B12=1,V12<>V11),PMT(V12/1200,MESES-B12+1,-Z11),W11),0) | X12: =Z11*V12/1200 | Y12: =IF(AND(BANCO_OK_4,B12<=MESES),IF(OR(B12=MESES,W12-X12>Z11),Z11,W12-X12),0) | Z12: =Z11-Y12 | AA12: =IF(AND(BANCO_OK_4,B12<=MESES),X12+Y12+VINC_MES_4,0)
B13: 5 | C13: =ROUNDUP(B13/12,0) | D13: =IF(AND(BANCO_OK_1,B13<=MESES),IF(OR(OF_TIPO_1="Fija",C13<=OF_ANIOS_INI_1),OF_TIN_1,MAX(0,EURIBOR+OF_DIF_1)),0) | E13: =IF(AND(BANCO_OK_1,B13<=MESES),IF(OR(B13=1,D13<>D12),PMT(D13/1200,MESES-B13+1,-H12),E12),0) | F13: =H12*D13/1200 | G13: =IF(AND(BANCO_OK_1,B13<=MESES),IF(OR(B13=MESES,E13-F13>H12),H12,E13-F13),0) | H13: =H12-G13 | I13: =IF(AND(BANCO_OK_1,B13<=MESES),F13+G13+VINC_MES_1,0) | J13: =IF(AND(BANCO_OK_2,B13<=MESES),IF(OR(OF_TIPO_2="Fija",C13<=OF_ANIOS_INI_2),OF_TIN_2,MAX(0,EURIBOR+OF_DIF_2)),0) | K13: =IF(AND(BANCO_OK_2,B13<=MESES),IF(OR(B13=1,J13<>J12),PMT(J13/1200,MESES-B13+1,-N12),K12),0) | L13: =N12*J13/1200 | M13: =IF(AND(BANCO_OK_2,B13<=MESES),IF(OR(B13=MESES,K13-L13>N12),N12,K13-L13),0) | N13: =N12-M13 | O13: =IF(AND(BANCO_OK_2,B13<=MESES),L13+M13+VINC_MES_2,0) | P13: =IF(AND(BANCO_OK_3,B13<=MESES),IF(OR(OF_TIPO_3="Fija",C13<=OF_ANIOS_INI_3),OF_TIN_3,MAX(0,EURIBOR+OF_DIF_3)),0) | Q13: =IF(AND(BANCO_OK_3,B13<=MESES),IF(OR(B13=1,P13<>P12),PMT(P13/1200,MESES-B13+1,-T12),Q12),0) | R13: =T12*P13/1200 | S13: =IF(AND(BANCO_OK_3,B13<=MESES),IF(OR(B13=MESES,Q13-R13>T12),T12,Q13-R13),0) | T13: =T12-S13 | U13: =IF(AND(BANCO_OK_3,B13<=MESES),R13+S13+VINC_MES_3,0) | V13: =IF(AND(BANCO_OK_4,B13<=MESES),IF(OR(OF_TIPO_4="Fija",C13<=OF_ANIOS_INI_4),OF_TIN_4,MAX(0,EURIBOR+OF_DIF_4)),0) | W13: =IF(AND(BANCO_OK_4,B13<=MESES),IF(OR(B13=1,V13<>V12),PMT(V13/1200,MESES-B13+1,-Z12),W12),0) | X13: =Z12*V13/1200 | Y13: =IF(AND(BANCO_OK_4,B13<=MESES),IF(OR(B13=MESES,W13-X13>Z12),Z12,W13-X13),0) | Z13: =Z12-Y13 | AA13: =IF(AND(BANCO_OK_4,B13<=MESES),X13+Y13+VINC_MES_4,0)
B14: 6 | C14: =ROUNDUP(B14/12,0) | D14: =IF(AND(BANCO_OK_1,B14<=MESES),IF(OR(OF_TIPO_1="Fija",C14<=OF_ANIOS_INI_1),OF_TIN_1,MAX(0,EURIBOR+OF_DIF_1)),0) | E14: =IF(AND(BANCO_OK_1,B14<=MESES),IF(OR(B14=1,D14<>D13),PMT(D14/1200,MESES-B14+1,-H13),E13),0) | F14: =H13*D14/1200 | G14: =IF(AND(BANCO_OK_1,B14<=MESES),IF(OR(B14=MESES,E14-F14>H13),H13,E14-F14),0) | H14: =H13-G14 | I14: =IF(AND(BANCO_OK_1,B14<=MESES),F14+G14+VINC_MES_1,0) | J14: =IF(AND(BANCO_OK_2,B14<=MESES),IF(OR(OF_TIPO_2="Fija",C14<=OF_ANIOS_INI_2),OF_TIN_2,MAX(0,EURIBOR+OF_DIF_2)),0) | K14: =IF(AND(BANCO_OK_2,B14<=MESES),IF(OR(B14=1,J14<>J13),PMT(J14/1200,MESES-B14+1,-N13),K13),0) | L14: =N13*J14/1200 | M14: =IF(AND(BANCO_OK_2,B14<=MESES),IF(OR(B14=MESES,K14-L14>N13),N13,K14-L14),0) | N14: =N13-M14 | O14: =IF(AND(BANCO_OK_2,B14<=MESES),L14+M14+VINC_MES_2,0) | P14: =IF(AND(BANCO_OK_3,B14<=MESES),IF(OR(OF_TIPO_3="Fija",C14<=OF_ANIOS_INI_3),OF_TIN_3,MAX(0,EURIBOR+OF_DIF_3)),0) | Q14: =IF(AND(BANCO_OK_3,B14<=MESES),IF(OR(B14=1,P14<>P13),PMT(P14/1200,MESES-B14+1,-T13),Q13),0) | R14: =T13*P14/1200 | S14: =IF(AND(BANCO_OK_3,B14<=MESES),IF(OR(B14=MESES,Q14-R14>T13),T13,Q14-R14),0) | T14: =T13-S14 | U14: =IF(AND(BANCO_OK_3,B14<=MESES),R14+S14+VINC_MES_3,0) | V14: =IF(AND(BANCO_OK_4,B14<=MESES),IF(OR(OF_TIPO_4="Fija",C14<=OF_ANIOS_INI_4),OF_TIN_4,MAX(0,EURIBOR+OF_DIF_4)),0) | W14: =IF(AND(BANCO_OK_4,B14<=MESES),IF(OR(B14=1,V14<>V13),PMT(V14/1200,MESES-B14+1,-Z13),W13),0) | X14: =Z13*V14/1200 | Y14: =IF(AND(BANCO_OK_4,B14<=MESES),IF(OR(B14=MESES,W14-X14>Z13),Z13,W14-X14),0) | Z14: =Z13-Y14 | AA14: =IF(AND(BANCO_OK_4,B14<=MESES),X14+Y14+VINC_MES_4,0)
B15: 7 | C15: =ROUNDUP(B15/12,0) | D15: =IF(AND(BANCO_OK_1,B15<=MESES),IF(OR(OF_TIPO_1="Fija",C15<=OF_ANIOS_INI_1),OF_TIN_1,MAX(0,EURIBOR+OF_DIF_1)),0) | E15: =IF(AND(BANCO_OK_1,B15<=MESES),IF(OR(B15=1,D15<>D14),PMT(D15/1200,MESES-B15+1,-H14),E14),0) | F15: =H14*D15/1200 | G15: =IF(AND(BANCO_OK_1,B15<=MESES),IF(OR(B15=MESES,E15-F15>H14),H14,E15-F15),0) | H15: =H14-G15 | I15: =IF(AND(BANCO_OK_1,B15<=MESES),F15+G15+VINC_MES_1,0) | J15: =IF(AND(BANCO_OK_2,B15<=MESES),IF(OR(OF_TIPO_2="Fija",C15<=OF_ANIOS_INI_2),OF_TIN_2,MAX(0,EURIBOR+OF_DIF_2)),0) | K15: =IF(AND(BANCO_OK_2,B15<=MESES),IF(OR(B15=1,J15<>J14),PMT(J15/1200,MESES-B15+1,-N14),K14),0) | L15: =N14*J15/1200 | M15: =IF(AND(BANCO_OK_2,B15<=MESES),IF(OR(B15=MESES,K15-L15>N14),N14,K15-L15),0) | N15: =N14-M15 | O15: =IF(AND(BANCO_OK_2,B15<=MESES),L15+M15+VINC_MES_2,0) | P15: =IF(AND(BANCO_OK_3,B15<=MESES),IF(OR(OF_TIPO_3="Fija",C15<=OF_ANIOS_INI_3),OF_TIN_3,MAX(0,EURIBOR+OF_DIF_3)),0) | Q15: =IF(AND(BANCO_OK_3,B15<=MESES),IF(OR(B15=1,P15<>P14),PMT(P15/1200,MESES-B15+1,-T14),Q14),0) | R15: =T14*P15/1200 | S15: =IF(AND(BANCO_OK_3,B15<=MESES),IF(OR(B15=MESES,Q15-R15>T14),T14,Q15-R15),0) | T15: =T14-S15 | U15: =IF(AND(BANCO_OK_3,B15<=MESES),R15+S15+VINC_MES_3,0) | V15: =IF(AND(BANCO_OK_4,B15<=MESES),IF(OR(OF_TIPO_4="Fija",C15<=OF_ANIOS_INI_4),OF_TIN_4,MAX(0,EURIBOR+OF_DIF_4)),0) | W15: =IF(AND(BANCO_OK_4,B15<=MESES),IF(OR(B15=1,V15<>V14),PMT(V15/1200,MESES-B15+1,-Z14),W14),0) | X15: =Z14*V15/1200 | Y15: =IF(AND(BANCO_OK_4,B15<=MESES),IF(OR(B15=MESES,W15-X15>Z14),Z14,W15-X15),0) | Z15: =Z14-Y15 | AA15: =IF(AND(BANCO_OK_4,B15<=MESES),X15+Y15+VINC_MES_4,0)
