Workbook
Name ANIO: 'Parámetros'!$C$8
Name IVA_GENERAL: 'Parámetros'!$C$10
Name IVA_REDUCIDO: 'Parámetros'!$C$11
Name IVA_SUPERREDUCIDO: 'Parámetros'!$C$12
Name PCT_130: 'Parámetros'!$C$14
Name MIN130_H1: 'Parámetros'!$C$15
Name MIN130_E1: 'Parámetros'!$C$16
Name MIN130_H2: 'Parámetros'!$C$17
Name MIN130_E2: 'Parámetros'!$C$18
Name MIN130_H3: 'Parámetros'!$C$19
Name MIN130_E3: 'Parámetros'!$C$20
Name MIN130_H4: 'Parámetros'!$C$21
Name MIN130_E4: 'Parámetros'!$C$22
Name TIPO_RETA: 'Parámetros'!$C$24
Name TARIFA_PLANA_EUR: 'Parámetros'!$C$25
Name GASTOS_GENERICOS: 'Parámetros'!$C$26
Name DJ_PCT: 'Parámetros'!$C$28
Name DJ_MAX: 'Parámetros'!$C$29
Name MIN_PERSONAL: 'Parámetros'!$C$31
Name MIN_65: 'Parámetros'!$C$32
Name MIN_75: 'Parámetros'!$C$33
Name MIN_DESC1: 'Parámetros'!$C$34
Name MIN_DESC2: 'Parámetros'!$C$35
Name MIN_DESC3: 'Parámetros'!$C$36
Name MIN_DESC4: 'Parámetros'!$C$37
Name MIN_MENOR3: 'Parámetros'!$C$38
Name ESC_COD: 'Escalas IRPF'!$B$7:$B$123
Name ESC_DESDE: 'Escalas IRPF'!$D$7:$D$123
Name ESC_DELTA: 'Escalas IRPF'!$F$7:$F$123
Name CCAA_COD: 'Escalas IRPF'!$H$7:$H$22
Name CCAA_NOM: 'Escalas IRPF'!$I$7:$I$22
Name CCAA_MINP: 'Escalas IRPF'!$J$7:$J$22
Name CCAA_BONIF: 'Escalas IRPF'!$K$7:$K$22
Name TITULAR: 'Mis datos'!$C$9
Name NIF_TITULAR: 'Mis datos'!$C$10
Name CCAA_NOMBRE: 'Mis datos'!$C$12
Name EDAD: 'Mis datos'!$C$13
Name HIJOS: 'Mis datos'!$C$14
Name HIJOS3: 'Mis datos'!$C$15
Name HIJOS100: 'Mis datos'!$C$16
Name TARIFA_PLANA: 'Mis datos'!$C$19
Name PRESENTA_130: 'Mis datos'!$C$20
Name REND_ANTERIOR: 'Mis datos'!$C$21
Name COMPENSAR_INICIAL: 'Mis datos'!$C$22
Name CCAA: 'Mis datos'!$C$24
Name REND_PREVISTO: 'Cuota autónomos'!$C$9
Name COMPUTABLE_MES: 'Cuota autónomos'!$C$10
Name TRAMO: 'Cuota autónomos'!$C$11
Name BASE_MIN: 'Cuota autónomos'!$C$12
Name CUOTA_PREVISTA: 'Cuota autónomos'!$C$14
Name CUOTA_MES: 'Cuota autónomos'!$E$18:$E$29
Name CUOTA_TRIM: 'Cuota autónomos'!$F$18:$F$29
Name CUOTA_ANUAL: 'Cuota autónomos'!$E$30
Name T_RMIN: 'Cuota autónomos'!$C$44:$C$58
Name T_RMAX: 'Cuota autónomos'!$D$44:$D$58
Name T_BMIN: 'Cuota autónomos'!$E$44:$E$58
Name T_BMAX: 'Cuota autónomos'!$F$44:$F$58
Name RES303_1: 'Modelo 303'!$D$19
Name PAGO303_1: 'Modelo 303'!$D$21
Name RES303_2: 'Modelo 303'!$E$19

Sheet Portada
C3: IMPUESTOCLARO
C5: Kit del autónomo 2027
C7: Tu libro de ingresos y gastos, los modelos 303 y 130 de cada trimestre, la cuota de autónomos por tramos y la estimación de la renta: todo se calcula solo a partir de tus facturas.
C10: Edición 2027 · parámetros a 2026-10-27 (provisionales)
C14: Empieza en tres pasos
B15: 1 | C15: Rellena «Mis datos» (comunidad, tarifa plana, rendimiento de 2026).
B16: 2 | C16: Apunta cada factura que emitas en «Ingresos» y cada gasto en «Gastos». Una fila por factura.
B17: 3 | C17: Mira el «Panel»: cuánto pagar en cada trimestre, cuándo y cuánto apartar. Copia las cifras en los modelos de la AEAT.
C19: Qué hay en este libro
C20: → Panel | D20: Resumen: a pagar en cada trimestre, renta estimada y cuánto apartar de cada factura
C21: → Mis datos | D21: Comunidad, familia, tarifa plana y datos de 2026
C22: → Ingresos | D22: Libro registro de facturas emitidas (400 filas)
C23: → Gastos | D23: Libro registro de facturas recibidas, con IVA deducible y % de afectación
C24: → Modelo 303 | D24: IVA de cada trimestre, con compensación automática y devolución en el 4T
C25: → Modelo 130 | D25: Pago fraccionado del IRPF acumulado, con retenciones y minoración
C26: → Cuota autónomos | D26: Tramo según rendimientos, cuota mes a mes y regularización estimada
C27: → Renta 2027 | D27: Estimación de la declaración: cuota estatal y autonómica, mínimos y resultado
C28: → Calendario 2027 | D28: Todas las fechas fiscales del año, con casilla de hecho
C29: → Parámetros | D29: Cifras oficiales que usan las fórmulas, con su fuente
C30: → Escalas IRPF | D30: Escala estatal y de cada comunidad
C32: Antes de usarlo
C33: Herramienta de cálculo orientativa para autónomos persona física en estimación directa simplificada. No es asesoramiento fiscal ni sustituye a los programas de la AEAT: revisa siempre el borrador oficial antes de presentar.
C34: Los parámetros de 2027 son provisionales: lo que aún no se ha publicado (tramos de cotización, escalas) se copia de 2026 y se indica en «Parámetros». Cuando cambien, descarga de nuevo el kit desde el mismo enlace de tu compra.
C35: Contenido preparado con ayuda de inteligencia artificial y revisado con las fuentes oficiales citadas (BOE, AEAT, Seguridad Social).
C36: Funciona en Excel, LibreOffice y Google Sheets (Archivo → Importar). Las hojas de cálculo están protegidas sin contraseña para que no borres una fórmula sin querer: Revisar → Desproteger hoja.
C38: https://impuestoclaro.vercel.app/kit-autonomo-2027/ | D38: Contacto: hola@numimates.com

Sheet Instrucciones
B2: Cómo se usa el kit | C2: ImpuestoClaro
B3: Léelo una vez: son cinco minutos
B6: 1. Antes de empezar
B7: • | C7: Guarda una copia con tu nombre y el año (por ejemplo, «kit-2027-ana.xlsx»). Trabaja siempre sobre tu copia.
B8: • | C8: En «Mis datos» elige tu comunidad autónoma: decide la escala autonómica de la renta. Si tienes tarifa plana, márcala.
B9: • | C9: Si ya llevabas facturas este año en otro sitio, cópialas en «Ingresos» y «Gastos»: una fila por factura, con su fecha.
B11: 2. Cada vez que facturas o pagas un gasto
B12: • | C12: Ingresos: fecha, número, cliente, base imponible (sin IVA), tipo de IVA y retención de IRPF que pones en la factura. El total y el trimestre salen solos.
B13: • | C13: Gastos: fecha, proveedor, base, tipo de IVA y categoría. Si el gasto solo es en parte de la actividad (móvil, coche), pon el % de afectación. Si la factura no te deja deducir el IVA (un ticket, por ejemplo), marca «No» en IVA deducible: entonces el IVA cuenta como gasto en el IRPF.
B14: • | C14: La cuota de autónomos no se apunta como gasto: el kit la suma sola desde la hoja «Cuota autónomos».
B16: 3. Cada trimestre
B17: • | C17: Abre «Modelo 303» y «Modelo 130»: las cifras de la columna del trimestre son las que copias en el formulario de la AEAT. El IVA negativo se compensa solo en el trimestre siguiente; en el 4T puedes pedir la devolución.
B18: • | C18: El 130 es acumulado desde enero: el kit ya resta lo que pagaste en los trimestres anteriores y las retenciones de tus facturas.
B19: • | C19: Las fechas límite están en cada modelo y en «Calendario 2027». Si domicilias el pago, el plazo acaba antes (día 15; 25 de enero en el 4T).
B21: 4. La cuota de autónomos
B22: • | C22: Pon en «Cuota autónomos» tu previsión de rendimiento neto del año (ingresos menos gastos). El kit busca tu tramo y la cuota mínima. Si cotizas por una base más alta, cámbiala mes a mes.
B23: • | C23: Al final, la hoja compara lo que has pagado con lo que corresponde a tus rendimientos reales: es la regularización que hará la Seguridad Social al año siguiente.
B25: 5. La renta
B26: • | C26: «Renta 2027» estima tu declaración con la escala estatal y la de tu comunidad, el mínimo personal y familiar y el 5 % de gastos de difícil justificación (máximo 2.000 €). Resta las retenciones y los pagos del 130.
B27: • | C27: Es una estimación: no incluye deducciones autonómicas, planes de pensiones, alquileres ni otras rentas. Te sirve para saber cuánto apartar.
B29: 6. En Google Sheets o LibreOffice
B30: • | C30: Google Sheets: Archivo → Importar → Subir, y elige «Reemplazar hoja de cálculo». Todo funciona igual, también las listas desplegables.
B31: • | C31: LibreOffice: ábrelo directamente. Si alguna cifra sale vacía, pulsa Ctrl+Mayús+F9 para recalcular.
B33: Ayuda
B34: • | C34: ¿Algo no cuadra? Escribe a hola@numimates.com con la hoja y la celda. Respondemos en días laborables.

Sheet Panel
B2: Panel 2027 | G2: ImpuestoClaro
B3: ="Titular: "&IF(TITULAR="","(escribe tu nombre en Mis datos)",TITULAR)
B7: A pagar a Hacienda y la Seguridad Social | C7: 1T | D7: 2T | E7: 3T | F7: 4T | G7: Año
B8: IVA (modelo 303) | C8: =PAGO303_1 | D8: =PAGO303_2 | E8: =PAGO303_3 | F8: =PAGO303_4 | G8: =SUM(C8:F8)
B9: IRPF (modelo 130) | C9: =PAGO130_1 | D9: =PAGO130_2 | E9: =PAGO130_3 | F9: =PAGO130_4 | G9: =SUM(C9:F9)
B10: Cuota de autónomos del trimestre | C10: =SUMIFS(CUOTA_MES,CUOTA_TRIM,1) | D10: =SUMIFS(CUOTA_MES,CUOTA_TRIM,2) | E10: =SUMIFS(CUOTA_MES,CUOTA_TRIM,3) | F10: =SUMIFS(CUOTA_MES,CUOTA_TRIM,4) | G10: =SUM(C10:F10)
B11: Total del trimestre | C11: =SUM(C8:C10) | D11: =SUM(D8:D10) | E11: =SUM(E8:E10) | F11: =SUM(F8:F10) | G11: =SUM(G8:G10)
B12: Último día para el 303 y el 130 | C12: 46497 | D12: 46588 | E12: 46680 | F12: 46783
B14: Tu año | C14: Importe
B15: Facturado (base sin IVA) | C15: ='Renta 2027'!C8
B16: Gastos deducibles | C16: ='Renta 2027'!C9
B17: Cuota de autónomos | C17: ='Renta 2027'!C11
B18: IRPF estimado del año | C18: =RENTA_TOTAL
B19: Renta: a pagar (+) o a devolver (−) en 2028 | C19: =RENTA_RESULTADO
B20: Te queda al mes | C20: ='Renta 2027'!C33
B22: Cuánto apartar de cada factura
B23: Del IVA que cobras: apártalo entero | C23: =1
B24: De la base, para IRPF y cuota (con tus cifras) | C24: =IF('Renta 2027'!C8>0,(RENTA_TOTAL-'Renta 2027'!C29+'Renta 2027'!C11)/'Renta 2027'!C8,0) | D24: IRPF del año (menos lo que ya te retienen) más la cuota, sobre lo facturado.
B26: Las cifras se actualizan solas al apuntar facturas. Estimación orientativa: no es asesoramiento fiscal.

Sheet Mis datos
B2: Mis datos | D2: ImpuestoClaro
B3: Se rellenan una vez al año
B6: Amarillo | C6: Escribe tú en las celdas amarillas. Las demás se calculan solas: no hace falta tocarlas.
B8: Quién eres
B9: Nombre y apellidos | D9: Aparece en la cabecera de los libros.
B10: NIF
B11: Actividad (epígrafe IAE o descripción)
B12: Comunidad autónoma de residencia | C12: Cataluña | D12: Decide la escala autonómica de la renta.
B13: Edad a 31 de diciembre | C13: 40 | D13: A partir de 65 años sube el mínimo personal.
B14: Hijos menores de 25 que conviven contigo | C14: 0 | D14: Para el mínimo por descendientes.
B15: De ellos, menores de 3 años | C15: 0
B16: ¿Te aplicas el mínimo por hijos entero? | C16: No | D16: «No» si lo repartís a medias con el otro progenitor (lo habitual).
B18: Seguridad Social y modelos
B19: ¿Tienes tarifa plana todo 2027? | C19: No | D19: Si solo es una parte del año, cámbialo mes a mes en «Cuota autónomos».
B20: ¿Presentas el modelo 130? | C20: Sí | D20: No estás obligado si en 2026 al menos el 70 % de tus ingresos llevaron retención.
B21: Rendimiento neto de 2026 (€) | C21: 20000 | D21: Casilla de rendimiento neto de la actividad de tu renta 2026: decide la minoración del 130.
B22: IVA a compensar que te quedó de 2026 (€) | C22: 0 | D22: Si el 4T de 2026 salió negativo y no pediste la devolución.
B24: Código de la comunidad (lo usan las fórmulas) | C24: =INDEX(CCAA_COD,MATCH(CCAA_NOMBRE,CCAA_NOM,0))

Sheet Ingresos
B2: Libro registro de facturas emitidas 2027 | N2: ImpuestoClaro
B3: Una fila por factura. Base sin IVA; el tipo de IVA y la retención, como en la factura.
B5: Amarillo | C5: Escribe tú en las celdas amarillas. Las demás se calculan solas: no hace falta tocarlas. | F5: ="Titular: "&IF(TITULAR="","—",TITULAR)&" · NIF: "&IF(NIF_TITULAR="","—",NIF_TITULAR)
B6: Las facturas de otro año (en gris) no cuentan. Totales del año: base | G6: =SUMIFS(G8:G407,N8:N407,ANIO) | I6: =SUMIFS(I8:I407,N8:N407,ANIO) | K6: =SUMIFS(K8:K407,N8:N407,ANIO) | L6: =SUMIFS(L8:L407,N8:N407,ANIO)
B7: Fecha | C7: Nº factura | D7: Cliente | E7: NIF cliente | F7: Concepto | G7: Base imponible | H7: IVA % | I7: Cuota IVA | J7: Ret. % | K7: Retención | L7: Total factura | M7: Trim. | N7: Año
I8: =IF(G8="","",ROUND(G8*N(H8)/100,2)) | K8: =IF(G8="","",ROUND(G8*N(J8)/100,2)) | L8: =IF(G8="","",G8+I8-K8) | M8: =IF(B8="","",ROUNDUP(MONTH(B8)/3,0)) | N8: =IF(B8="","",YEAR(B8))
I9: =IF(G9="","",ROUND(G9*N(H9)/100,2)) | K9: =IF(G9="","",ROUND(G9*N(J9)/100,2)) | L9: =IF(G9="","",G9+I9-K9) | M9: =IF(B9="","",ROUNDUP(MONTH(B9)/3,0)) | N9: =IF(B9="","",YEAR(B9))
I10: =IF(G10="","",ROUND(G10*N(H10)/100,2)) | K10: =IF(G10="","",ROUND(G10*N(J10)/100,2)) | L10: =IF(G10="","",G10+I10-K10) | M10: =IF(B10="","",ROUNDUP(MONTH(B10)/3,0)) | N10: =IF(B10="","",YEAR(B10))
I11: =IF(G11="","",ROUND(G11*N(H11)/100,2)) | K11: =IF(G11="","",ROUND(G11*N(J11)/100,2)) | L11: =IF(G11="","",G11+I11-K11) | M11: =IF(B11="","",ROUNDUP(MONTH(B11)/3,0)) | N11: =IF(B11="","",YEAR(B11))
I12: =IF(G12="","",ROUND(G12*N(H12)/100,2)) | K12: =IF(G12="","",ROUND(G12*N(J12)/100,2)) | L12: =IF(G12="","",G12+I12-K12) | M12: =IF(B12="","",ROUNDUP(MONTH(B12)/3,0)) | N12: =IF(B12="","",YEAR(B12))
I13: =IF(G13="","",ROUND(G13*N(H13)/100,2)) | K13: =IF(G13="","",ROUND(G13*N(J13)/100,2)) | L13: =IF(G13="","",G13+I13-K13) | M13: =IF(B13="","",ROUNDUP(MONTH(B13)/3,0)) | N13: =IF(B13="","",YEAR(B13))
I14: =IF(G14="","",ROUND(G14*N(H14)/100,2)) | K14: =IF(G14="","",ROUND(G14*N(J14)/100,2)) | L14: =IF(G14="","",G14+I14-K14) | M14: =IF(B14="","",ROUNDUP(MONTH(B14)/3,0)) | N14: =IF(B14="","",YEAR(B14))
I15: =IF(G15="","",ROUND(G15*N(H15)/100,2)) | K15: =IF(G15="","",ROUND(G15*N(J15)/100,2)) | L15: =IF(G15="","",G15+I15-K15) | M15: =IF(B15="","",ROUNDUP(MONTH(B15)/3,0)) | N15: =IF(B15="","",YEAR(B15))
I16: =IF(G16="","",ROUND(G16*N(H16)/100,2)) | K16: =IF(G16="","",ROUND(G16*N(J16)/100,2)) | L16: =IF(G16="","",G16+I16-K16) | M16: =IF(B16="","",ROUNDUP(MONTH(B16)/3,0)) | N16: =IF(B16="","",YEAR(B16))
I17: =IF(G17="","",ROUND(G17*N(H17)/100,2)) | K17: =IF(G17="","",ROUND(G17*N(J17)/100,2)) | L17: =IF(G17="","",G17+I17-K17) | M17: =IF(B17="","",ROUNDUP(MONTH(B17)/3,0)) | N17: =IF(B17="","",YEAR(B17))
I18: =IF(G18="","",ROUND(G18*N(H18)/100,2)) | K18: =IF(G18="","",ROUND(G18*N(J18)/100,2)) | L18: =IF(G18="","",G18+I18-K18) | M18: =IF(B18="","",ROUNDUP(MONTH(B18)/3,0)) | N18: =IF(B18="","",YEAR(B18))
I19: =IF(G19="","",ROUND(G19*N(H19)/100,2)) | K19: =IF(G19="","",ROUND(G19*N(J19)/100,2)) | L19: =IF(G19="","",G19+I19-K19) | M19: =IF(B19="","",ROUNDUP(MONTH(B19)/3,0)) | N19: =IF(B19="","",YEAR(B19))
... I407: =IF(G407="","",ROUND(G407*N(H407)/100,2)) | K407: =IF(G407="","",ROUND(G407*N(J407)/100,2)) | L407: =IF(G407="","",G407+I407-K407) | M407: =IF(B407="","",ROUNDUP(MONTH(B407)/3,0)) | N407: =IF(B407="","",YEAR(B407))

Sheet Gastos
B2: Libro registro de facturas recibidas 2027 | P2: ImpuestoClaro
B3: Gastos de la actividad. La cuota de autónomos no se apunta aquí: se suma sola.
B5: Amarillo | C5: Escribe tú en las celdas amarillas. Las demás se calculan solas: no hace falta tocarlas.
B6: Vacío en «¿IVA deducible?» = Sí; vacío en «% afectación» = 100 %. Totales del año: | H6: =SUMIFS(H8:H407,P8:P407,ANIO) | M6: =SUMIFS(M8:M407,P8:P407,ANIO) | N6: =SUMIFS(N8:N407,P8:P407,ANIO)
B7: Fecha | C7: Nº factura | D7: Proveedor | E7: NIF proveedor | F7: Concepto | G7: Categoría | H7: Base imponible | I7: IVA % | J7: Cuota IVA | K7: ¿IVA deducible? | L7: % afectación | M7: IVA deducible | N7: Gasto deducible IRPF | O7: Trim. | P7: Año
J8: =IF(H8="","",ROUND(H8*N(I8)/100,2)) | M8: =IF(H8="","",IF(K8="No",0,H8*N(I8)/100*IF(L8="",100,L8)/100)) | N8: =IF(H8="","",H8*IF(L8="",100,L8)/100+IF(K8="No",H8*N(I8)/100*IF(L8="",100,L8)/100,0)) | O8: =IF(B8="","",ROUNDUP(MONTH(B8)/3,0)) | P8: =IF(B8="","",YEAR(B8))
J9: =IF(H9="","",ROUND(H9*N(I9)/100,2)) | M9: =IF(H9="","",IF(K9="No",0,H9*N(I9)/100*IF(L9="",100,L9)/100)) | N9: =IF(H9="","",H9*IF(L9="",100,L9)/100+IF(K9="No",H9*N(I9)/100*IF(L9="",100,L9)/100,0)) | O9: =IF(B9="","",ROUNDUP(MONTH(B9)/3,0)) | P9: =IF(B9="","",YEAR(B9))
J10: =IF(H10="","",ROUND(H10*N(I10)/100,2)) | M10: =IF(H10="","",IF(K10="No",0,H10*N(I10)/100*IF(L10="",100,L10)/100)) | N10: =IF(H10="","",H10*IF(L10="",100,L10)/100+IF(K10="No",H10*N(I10)/100*IF(L10="",100,L10)/100,0)) | O10: =IF(B10="","",ROUNDUP(MONTH(B10)/3,0)) | P10: =IF(B10="","",YEAR(B10))
J11: =IF(H11="","",ROUND(H11*N(I11)/100,2)) | M11: =IF(H11="","",IF(K11="No",0,H11*N(I11)/100*IF(L11="",100,L11)/100)) | N11: =IF(H11="","",H11*IF(L11="",100,L11)/100+IF(K11="No",H11*N(I11)/100*IF(L11="",100,L11)/100,0)) | O11: =IF(B11="","",ROUNDUP(MONTH(B11)/3,0)) | P11: =IF(B11="","",YEAR(B11))
J12: =IF(H12="","",ROUND(H12*N(I12)/100,2)) | M12: =IF(H12="","",IF(K12="No",0,H12*N(I12)/100*IF(L12="",100,L12)/100)) | N12: =IF(H12="","",H12*IF(L12="",100,L12)/100+IF(K12="No",H12*N(I12)/100*IF(L12="",100,L12)/100,0)) | O12: =IF(B12="","",ROUNDUP(MONTH(B12)/3,0)) | P12: =IF(B12="","",YEAR(B12))
J13: =IF(H13="","",ROUND(H13*N(I13)/100,2)) | M13: =IF(H13="","",IF(K13="No",0,H13*N(I13)/100*IF(L13="",100,L13)/100)) | N13: =IF(H13="","",H13*IF(L13="",100,L13)/100+IF(K13="No",H13*N(I13)/100*IF(L13="",100,L13)/100,0)) | O13: =IF(B13="","",ROUNDUP(MONTH(B13)/3,0)) | P13: =IF(B13="","",YEAR(B13))
J14: =IF(H14="","",ROUND(H14*N(I14)/100,2)) | M14: =IF(H14="","",IF(K14="No",0,H14*N(I14)/100*IF(L14="",100,L14)/100)) | N14: =IF(H14="","",H14*IF(L14="",100,L14)/100+IF(K14="No",H14*N(I14)/100*IF(L14="",100,L14)/100,0)) | O14: =IF(B14="","",ROUNDUP(MONTH(B14)/3,0)) | P14: =IF(B14="","",YEAR(B14))
J15: =IF(H15="","",ROUND(H15*N(I15)/100,2)) | M15: =IF(H15="","",IF(K15="No",0,H15*N(I15)/100*IF(L15="",100,L15)/100)) | N15: =IF(H15="","",H15*IF(L15="",100,L15)/100+IF(K15="No",H15*N(I15)/100*IF(L15="",100,L15)/100,0)) | O15: =IF(B15="","",ROUNDUP(MONTH(B15)/3,0)) | P15: =IF(B15="","",YEAR(B15))
J16: =IF(H16="","",ROUND(H16*N(I16)/100,2)) | M16: =IF(H16="","",IF(K16="No",0,H16*N(I16)/100*IF(L16="",100,L16)/100)) | N16: =IF(H16="","",H16*IF(L16="",100,L16)/100+IF(K16="No",H16*N(I16)/100*IF(L16="",100,L16)/100,0)) | O16: =IF(B16="","",ROUNDUP(MONTH(B16)/3,0)) | P16: =IF(B16="","",YEAR(B16))
J17: =IF(H17="","",ROUND(H17*N(I17)/100,2)) | M17: =IF(H17="","",IF(K17="No",0,H17*N(I17)/100*IF(L17="",100,L17)/100)) | N17: =IF(H17="","",H17*IF(L17="",100,L17)/100+IF(K17="No",H17*N(I17)/100*IF(L17="",100,L17)/100,0)) | O17: =IF(B17="","",ROUNDUP(MONTH(B17)/3,0)) | P17: =IF(B17="","",YEAR(B17))
J18: =IF(H18="","",ROUND(H18*N(I18)/100,2)) | M18: =IF(H18="","",IF(K18="No",0,H18*N(I18)/100*IF(L18="",100,L18)/100)) | N18: =IF(H18="","",H18*IF(L18="",100,L18)/100+IF(K18="No",H18*N(I18)/100*IF(L18="",100,L18)/100,0)) | O18: =IF(B18="","",ROUNDUP(MONTH(B18)/3,0)) | P18: =IF(B18="","",YEAR(B18))
J19: =IF(H19="","",ROUND(H19*N(I19)/100,2)) | M19: =IF(H19="","",IF(K19="No",0,H19*N(I19)/100*IF(L19="",100,L19)/100)) | N19: =IF(H19="","",H19*IF(L19="",100,L19)/100+IF(K19="No",H19*N(I19)/100*IF(L19="",100,L19)/100,0)) | O19: =IF(B19="","",ROUNDUP(MONTH(B19)/3,0)) | P19: =IF(B19="","",YEAR(B19))
... J407: =IF(H407="","",ROUND(H407*N(I407)/100,2)) | M407: =IF(H407="","",IF(K407="No",0,H407*N(I407)/100*IF(L407="",100,L407)/100)) | N407: =IF(H407="","",H407*IF(L407="",100,L407)/100+IF(K407="No",H407*N(I407)/100*IF(L407="",100,L407)/100,0)) | O407: =IF(B407="","",ROUNDUP(MONTH(B407)/3,0)) | P407: =IF(B407="","",YEAR(B407))

Sheet Modelo 303
B2: Modelo 303 · IVA 2027 | H2: ImpuestoClaro
B3: Se calcula solo con tus libros. Copia la columna del trimestre en el formulario de la AEAT.
B7: Concepto | D7: 1T (ene-mar) | E7: 2T (abr-jun) | F7: 3T (jul-sep) | G7: 4T (oct-dic) | H7: Año
B8: Base imponible al tipo general | D8: =SUMIFS(Ingresos!$G$8:$G$407,Ingresos!$H$8:$H$407,IVA_GENERAL,Ingresos!$M$8:$M$407,1,Ingresos!$N$8:$N$407,ANIO) | E8: =SUMIFS(Ingresos!$G$8:$G$407,Ingresos!$H$8:$H$407,IVA_GENERAL,Ingresos!$M$8:$M$407,2,Ingresos!$N$8:$N$407,ANIO) | F8: =SUMIFS(Ingresos!$G$8:$G$407,Ingresos!$H$8:$H$407,IVA_GENERAL,Ingresos!$M$8:$M$407,3,Ingresos!$N$8:$N$407,ANIO) | G8: =SUMIFS(Ingresos!$G$8:$G$407,Ingresos!$H$8:$H$407,IVA_GENERAL,Ingresos!$M$8:$M$407,4,Ingresos!$N$8:$N$407,ANIO) | H8: =SUM(D8:G8)
B9: Cuota devengada al tipo general | D9: =D8*IVA_GENERAL/100 | E9: =E8*IVA_GENERAL/100 | F9: =F8*IVA_GENERAL/100 | G9: =G8*IVA_GENERAL/100 | H9: =SUM(D9:G9)
B10: Base imponible al tipo reducido | D10: =SUMIFS(Ingresos!$G$8:$G$407,Ingresos!$H$8:$H$407,IVA_REDUCIDO,Ingresos!$M$8:$M$407,1,Ingresos!$N$8:$N$407,ANIO) | E10: =SUMIFS(Ingresos!$G$8:$G$407,Ingresos!$H$8:$H$407,IVA_REDUCIDO,Ingresos!$M$8:$M$407,2,Ingresos!$N$8:$N$407,ANIO) | F10: =SUMIFS(Ingresos!$G$8:$G$407,Ingresos!$H$8:$H$407,IVA_REDUCIDO,Ingresos!$M$8:$M$407,3,Ingresos!$N$8:$N$407,ANIO) | G10: =SUMIFS(Ingresos!$G$8:$G$407,Ingresos!$H$8:$H$407,IVA_REDUCIDO,Ingresos!$M$8:$M$407,4,Ingresos!$N$8:$N$407,ANIO) | H10: =SUM(D10:G10)
B11: Cuota devengada al tipo reducido | D11: =D10*IVA_REDUCIDO/100 | E11: =E10*IVA_REDUCIDO/100 | F11: =F10*IVA_REDUCIDO/100 | G11: =G10*IVA_REDUCIDO/100 | H11: =SUM(D11:G11)
B12: Base imponible al tipo superreducido | D12: =SUMIFS(Ingresos!$G$8:$G$407,Ingresos!$H$8:$H$407,IVA_SUPERREDUCIDO,Ingresos!$M$8:$M$407,1,Ingresos!$N$8:$N$407,ANIO) | E12: =SUMIFS(Ingresos!$G$8:$G$407,Ingresos!$H$8:$H$407,IVA_SUPERREDUCIDO,Ingresos!$M$8:$M$407,2,Ingresos!$N$8:$N$407,ANIO) | F12: =SUMIFS(Ingresos!$G$8:$G$407,Ingresos!$H$8:$H$407,IVA_SUPERREDUCIDO,Ingresos!$M$8:$M$407,3,Ingresos!$N$8:$N$407,ANIO) | G12: =SUMIFS(Ingresos!$G$8:$G$407,Ingresos!$H$8:$H$407,IVA_SUPERREDUCIDO,Ingresos!$M$8:$M$407,4,Ingresos!$N$8:$N$407,ANIO) | H12: =SUM(D12:G12)
B13: Cuota devengada al tipo superreducido | D13: =D12*IVA_SUPERREDUCIDO/100 | E13: =E12*IVA_SUPERREDUCIDO/100 | F13: =F12*IVA_SUPERREDUCIDO/100 | G13: =G12*IVA_SUPERREDUCIDO/100 | H13: =SUM(D13:G13)
B14: Operaciones exentas o sin IVA (informativo) | D14: =SUMIFS(Ingresos!$G$8:$G$407,Ingresos!$H$8:$H$407,0,Ingresos!$M$8:$M$407,1,Ingresos!$N$8:$N$407,ANIO) | E14: =SUMIFS(Ingresos!$G$8:$G$407,Ingresos!$H$8:$H$407,0,Ingresos!$M$8:$M$407,2,Ingresos!$N$8:$N$407,ANIO) | F14: =SUMIFS(Ingresos!$G$8:$G$407,Ingresos!$H$8:$H$407,0,Ingresos!$M$8:$M$407,3,Ingresos!$N$8:$N$407,ANIO) | G14: =SUMIFS(Ingresos!$G$8:$G$407,Ingresos!$H$8:$H$407,0,Ingresos!$M$8:$M$407,4,Ingresos!$N$8:$N$407,ANIO) | H14: =SUM(D14:G14)
B15: Total cuota devengada | D15: =D9+D11+D13 | E15: =E9+E11+E13 | F15: =F9+F11+F13 | G15: =G9+G11+G13 | H15: =SUM(D15:G15)
B16: IVA soportado deducible (gastos) | D16: =SUMIFS(Gastos!$M$8:$M$407,Gastos!$O$8:$O$407,1,Gastos!$P$8:$P$407,ANIO) | E16: =SUMIFS(Gastos!$M$8:$M$407,Gastos!$O$8:$O$407,2,Gastos!$P$8:$P$407,ANIO) | F16: =SUMIFS(Gastos!$M$8:$M$407,Gastos!$O$8:$O$407,3,Gastos!$P$8:$P$407,ANIO) | G16: =SUMIFS(Gastos!$M$8:$M$407,Gastos!$O$8:$O$407,4,Gastos!$P$8:$P$407,ANIO) | H16: =SUM(D16:G16)
B17: Diferencia (devengado − soportado) | D17: =D15-D16 | E17: =E15-E16 | F17: =F15-F16 | G17: =G15-G16 | H17: =SUM(D17:G17)
B18: Cuotas a compensar de periodos anteriores | D18: =COMPENSAR_INICIAL | E18: =MAX(0,-D19) | F18: =MAX(0,-E19) | G18: =MAX(0,-F19)
B19: Resultado de la liquidación | D19: =D17-D18 | E19: =E17-E18 | F19: =F17-F18 | G19: =G17-G18 | H19: =SUM(D19:G19)
B21: A INGRESAR | D21: =MAX(0,D19) | E21: =MAX(0,E19) | F21: =MAX(0,F19) | G21: =MAX(0,G19) | H21: =SUM(D21:G21)
B22: A compensar en el trimestre siguiente | D22: =IF(D19<0,-D19,0) | E22: =IF(E19<0,-E19,0) | F22: =IF(F19<0,-F19,0) | G22: =0
B23: A devolver (solo en el 4T, si lo pides) | D23: =0 | E23: =0 | F23: =0 | G23: =IF(G19<0,-G19,0)
B25: Plazo de presentación | D25: 1-20 abril | E25: 1-20 julio | F25: 1-20 octubre | G25: 1-30 enero 2028
B26: Último día (si cae en fin de semana, el lunes) | D26: 46497 | E26: 46588 | F26: 46680 | G26: 46783
B28: Trimestral; mensual (1-30 del mes siguiente, enero hasta 30) para grandes empresas, REDEME y grupos. Domiciliación hasta el día 15 (25 de enero en el 4T). En enero también se presenta el resumen anual (modelo 390) con los totales de la columna «Año».

Sheet Modelo 130
B2: Modelo 130 · pago fraccionado del IRPF 2027 | G2: ImpuestoClaro
B3: Acumulado desde el 1 de enero hasta el final de cada trimestre
B7: Concepto | D7: 1T | E7: 2T | F7: 3T | G7: 4T
B8: Ingresos computables acumulados | D8: =SUMIFS(Ingresos!$G$8:$G$407,Ingresos!$M$8:$M$407,"<="&1,Ingresos!$N$8:$N$407,ANIO) | E8: =SUMIFS(Ingresos!$G$8:$G$407,Ingresos!$M$8:$M$407,"<="&2,Ingresos!$N$8:$N$407,ANIO) | F8: =SUMIFS(Ingresos!$G$8:$G$407,Ingresos!$M$8:$M$407,"<="&3,Ingresos!$N$8:$N$407,ANIO) | G8: =SUMIFS(Ingresos!$G$8:$G$407,Ingresos!$M$8:$M$407,"<="&4,Ingresos!$N$8:$N$407,ANIO)
B9: Gastos deducibles acumulados (libro de gastos) | D9: =SUMIFS(Gastos!$N$8:$N$407,Gastos!$O$8:$O$407,"<="&1,Gastos!$P$8:$P$407,ANIO) | E9: =SUMIFS(Gastos!$N$8:$N$407,Gastos!$O$8:$O$407,"<="&2,Gastos!$P$8:$P$407,ANIO) | F9: =SUMIFS(Gastos!$N$8:$N$407,Gastos!$O$8:$O$407,"<="&3,Gastos!$P$8:$P$407,ANIO) | G9: =SUMIFS(Gastos!$N$8:$N$407,Gastos!$O$8:$O$407,"<="&4,Gastos!$P$8:$P$407,ANIO)
B10: Cuota de autónomos acumulada | D10: =SUMIFS(CUOTA_MES,CUOTA_TRIM,"<="&1) | E10: =SUMIFS(CUOTA_MES,CUOTA_TRIM,"<="&2) | F10: =SUMIFS(CUOTA_MES,CUOTA_TRIM,"<="&3) | G10: =SUMIFS(CUOTA_MES,CUOTA_TRIM,"<="&4)
B11: Rendimiento neto acumulado | D11: =D8-D9-D10 | E11: =E8-E9-E10 | F11: =F8-F9-F10 | G11: =G8-G9-G10
B12: Pago fraccionado (20 % del rendimiento positivo) | D12: =MAX(0,D11)*PCT_130/100 | E12: =MAX(0,E11)*PCT_130/100 | F12: =MAX(0,F11)*PCT_130/100 | G12: =MAX(0,G11)*PCT_130/100
B13: Retenciones de tus facturas, acumuladas | D13: =SUMIFS(Ingresos!$K$8:$K$407,Ingresos!$M$8:$M$407,"<="&1,Ingresos!$N$8:$N$407,ANIO) | E13: =SUMIFS(Ingresos!$K$8:$K$407,Ingresos!$M$8:$M$407,"<="&2,Ingresos!$N$8:$N$407,ANIO) | F13: =SUMIFS(Ingresos!$K$8:$K$407,Ingresos!$M$8:$M$407,"<="&3,Ingresos!$N$8:$N$407,ANIO) | G13: =SUMIFS(Ingresos!$K$8:$K$407,Ingresos!$M$8:$M$407,"<="&4,Ingresos!$N$8:$N$407,ANIO)
B14: Pagos de los 130 anteriores del año | D14: =0 | E14: =SUM($D17:D17) | F14: =SUM($D17:E17) | G14: =SUM($D17:F17)
B15: Minoración por rendimientos bajos en 2026 | D15: =IF(REND_ANTERIOR<=MIN130_H1,MIN130_E1,IF(REND_ANTERIOR<=MIN130_H2,MIN130_E2,IF(REND_ANTERIOR<=MIN130_H3,MIN130_E3,IF(REND_ANTERIOR<=MIN130_H4,MIN130_E4,0))))*1 | E15: =IF(REND_ANTERIOR<=MIN130_H1,MIN130_E1,IF(REND_ANTERIOR<=MIN130_H2,MIN130_E2,IF(REND_ANTERIOR<=MIN130_H3,MIN130_E3,IF(REND_ANTERIOR<=MIN130_H4,MIN130_E4,0))))*2 | F15: =IF(REND_ANTERIOR<=MIN130_H1,MIN130_E1,IF(REND_ANTERIOR<=MIN130_H2,MIN130_E2,IF(REND_ANTERIOR<=MIN130_H3,MIN130_E3,IF(REND_ANTERIOR<=MIN130_H4,MIN130_E4,0))))*3 | G15: =IF(REND_ANTERIOR<=MIN130_H1,MIN130_E1,IF(REND_ANTERIOR<=MIN130_H2,MIN130_E2,IF(REND_ANTERIOR<=MIN130_H3,MIN130_E3,IF(REND_ANTERIOR<=MIN130_H4,MIN130_E4,0))))*4
B16: Resultado | D16: =D12-D13-D14-D15 | E16: =E12-E13-E14-E15 | F16: =F12-F13-F14-F15 | G16: =G12-G13-G14-G15
B17: A INGRESAR | D17: =IF(PRESENTA_130="No",0,MAX(0,D16)) | E17: =IF(PRESENTA_130="No",0,MAX(0,E16)) | F17: =IF(PRESENTA_130="No",0,MAX(0,F16)) | G17: =IF(PRESENTA_130="No",0,MAX(0,G16))
B19: Último día de presentación | D19: 46497 | E19: 46588 | F19: 46680 | G19: 46783
B21: =IF(PRESENTA_130="No","Has indicado que no presentas el 130 (más del 70 % de tus ingresos de 2026 llevaron retención): los importes son solo informativos.","Un resultado negativo no se devuelve: se resta solo en los trimestres siguientes, porque el cálculo es acumulado.")
B22: 20 % del rendimiento neto acumulado desde el 1 de enero menos pagos y retenciones anteriores. No obligado si >= 70 % de ingresos profesionales tuvieron retención el año anterior. Minoración: Minoración trimestral del pago fraccionado según los rendimientos netos del año anterior (art. 110.3.c RIRPF): 100 € si no superan 9.000 €, 75 € hasta 10.000 €, 50 € hasta 11.000 € y 25 € hasta 12.000 €. Se acumula por trimestres.

Sheet Cuota autónomos
B2: Cuota de autónomos 2027 | H2: ImpuestoClaro
B3: Sistema de cotización por ingresos reales: tramo según el rendimiento neto previsto
B6: Amarillo | C6: Escribe tú en las celdas amarillas. Las demás se calculan solas: no hace falta tocarlas.
B8: 1. Tu tramo con la previsión de rendimientos
B9: Rendimiento neto previsto del año (€) | C9: =MAX(0,'Renta 2027'!C8-'Renta 2027'!C9) | D9: Ingresos menos gastos, sin la cuota. Por defecto, los de tus libros; cámbialo por tu previsión al principio del año.
B10: Rendimiento computable mensual (con la deducción por gastos genéricos) | C10: =REND_PREVISTO*(1-GASTOS_GENERICOS/100)/12
B11: Tramo | C11: =MIN(COUNT(T_RMIN),COUNTIF(T_RMAX,"<"&COMPUTABLE_MES)+1)
B12: Base mínima de tu tramo (€/mes) | C12: =INDEX(T_BMIN,TRAMO)
B13: Base máxima de tu tramo (€/mes) | C13: =INDEX(T_BMAX,TRAMO)
B14: Cuota mensual con la base mínima | C14: =IF(TARIFA_PLANA="Sí",TARIFA_PLANA_EUR,BASE_MIN*TIPO_RETA/100) | D14: ="Tipo de cotización: "&TIPO_RETA&" %"&IF(TARIFA_PLANA="Sí"," · tarifa plana","")
B16: 2. Mes a mes (cambia la base si cotizas por más)
B17: Mes | C17: Tarifa plana | D17: Base de cotización | E17: Cuota del mes | F17: Trimestre | G17: Rendimiento real del mes | H17: Cargo previsto
B18: Enero | C18: =TARIFA_PLANA | D18: =BASE_MIN | E18: =IF(C18="Sí",TARIFA_PLANA_EUR,D18*TIPO_RETA/100) | F18: 1 | G18: =SUMIFS(Ingresos!$G$8:$G$407,Ingresos!$B$8:$B$407,">="&DATE(2027,1,1),Ingresos!$B$8:$B$407,"<="&DATE(2027,1,31))-SUMIFS(Gastos!$N$8:$N$407,Gastos!$B$8:$B$407,">="&DATE(2027,1,1),Gastos!$B$8:$B$407,"<="&DATE(2027,1,31)) | H18: 46416
B19: Febrero | C19: =TARIFA_PLANA | D19: =BASE_MIN | E19: =IF(C19="Sí",TARIFA_PLANA_EUR,D19*TIPO_RETA/100) | F19: 1 | G19: =SUMIFS(Ingresos!$G$8:$G$407,Ingresos!$B$8:$B$407,">="&DATE(2027,2,1),Ingresos!$B$8:$B$407,"<="&DATE(2027,2,28))-SUMIFS(Gastos!$N$8:$N$407,Gastos!$B$8:$B$407,">="&DATE(2027,2,1),Gastos!$B$8:$B$407,"<="&DATE(2027,2,28)) | H19: 46444
B20: Marzo | C20: =TARIFA_PLANA | D20: =BASE_MIN | E20: =IF(C20="Sí",TARIFA_PLANA_EUR,D20*TIPO_RETA/100) | F20: 1 | G20: =SUMIFS(Ingresos!$G$8:$G$407,Ingresos!$B$8:$B$407,">="&DATE(2027,3,1),Ingresos!$B$8:$B$407,"<="&DATE(2027,3,31))-SUMIFS(Gastos!$N$8:$N$407,Gastos!$B$8:$B$407,">="&DATE(2027,3,1),Gastos!$B$8:$B$407,"<="&DATE(2027,3,31)) | H20: 46477
B21: Abril | C21: =TARIFA_PLANA | D21: =BASE_MIN | E21: =IF(C21="Sí",TARIFA_PLANA_EUR,D21*TIPO_RETA/100) | F21: 2 | G21: =SUMIFS(Ingresos!$G$8:$G$407,Ingresos!$B$8:$B$407,">="&DATE(2027,4,1),Ingresos!$B$8:$B$407,"<="&DATE(2027,4,30))-SUMIFS(Gastos!$N$8:$N$407,Gastos!$B$8:$B$407,">="&DATE(2027,4,1),Gastos!$B$8:$B$407,"<="&DATE(2027,4,30)) | H21: 46507
B22: Mayo | C22: =TARIFA_PLANA | D22: =BASE_MIN | E22: =IF(C22="Sí",TARIFA_PLANA_EUR,D22*TIPO_RETA/100) | F22: 2 | G22: =SUMIFS(Ingresos!$G$8:$G$407,Ingresos!$B$8:$B$407,">="&DATE(2027,5,1),Ingresos!$B$8:$B$407,"<="&DATE(2027,5,31))-SUMIFS(Gastos!$N$8:$N$407,Gastos!$B$8:$B$407,">="&DATE(2027,5,1),Gastos!$B$8:$B$407,"<="&DATE(2027,5,31)) | H22: 46538
B23: Junio | C23: =TARIFA_PLANA | D23: =BASE_MIN | E23: =IF(C23="Sí",TARIFA_PLANA_EUR,D23*TIPO_RETA/100) | F23: 2 | G23: =SUMIFS(Ingresos!$G$8:$G$407,Ingresos!$B$8:$B$407,">="&DATE(2027,6,1),Ingresos!$B$8:$B$407,"<="&DATE(2027,6,30))-SUMIFS(Gastos!$N$8:$N$407,Gastos!$B$8:$B$407,">="&DATE(2027,6,1),Gastos!$B$8:$B$407,"<="&DATE(2027,6,30)) | H23: 46568
B24: Julio | C24: =TARIFA_PLANA | D24: =BASE_MIN | E24: =IF(C24="Sí",TARIFA_PLANA_EUR,D24*TIPO_RETA/100) | F24: 3 | G24: =SUMIFS(Ingresos!$G$8:$G$407,Ingresos!$B$8:$B$407,">="&DATE(2027,7,1),Ingresos!$B$8:$B$407,"<="&DATE(2027,7,31))-SUMIFS(Gastos!$N$8:$N$407,Gastos!$B$8:$B$407,">="&DATE(2027,7,1),Gastos!$B$8:$B$407,"<="&DATE(2027,7,31)) | H24: 46598
B25: Agosto | C25: =TARIFA_PLANA | D25: =BASE_MIN | E25: =IF(C25="Sí",TARIFA_PLANA_EUR,D25*TIPO_RETA/100) | F25: 3 | G25: =SUMIFS(Ingresos!$G$8:$G$407,Ingresos!$B$8:$B$407,">="&DATE(2027,8,1),Ingresos!$B$8:$B$407,"<="&DATE(2027,8,31))-SUMIFS(Gastos!$N$8:$N$407,Gastos!$B$8:$B$407,">="&DATE(2027,8,1),Gastos!$B$8:$B$407,"<="&DATE(2027,8,31)) | H25: 46630
B26: Septiembre | C26: =TARIFA_PLANA | D26: =BASE_MIN | E26: =IF(C26="Sí",TARIFA_PLANA_EUR,D26*TIPO_RETA/100) | F26: 3 | G26: =SUMIFS(Ingresos!$G$8:$G$407,Ingresos!$B$8:$B$407,">="&DATE(2027,9,1),Ingresos!$B$8:$B$407,"<="&DATE(2027,9,30))-SUMIFS(Gastos!$N$8:$N$407,Gastos!$B$8:$B$407,">="&DATE(2027,9,1),Gastos!$B$8:$B$407,"<="&DATE(2027,9,30)) | H26: 46660
B27: Octubre | C27: =TARIFA_PLANA | D27: =BASE_MIN | E27: =IF(C27="Sí",TARIFA_PLANA_EUR,D27*TIPO_RETA/100) | F27: 4 | G27: =SUMIFS(Ingresos!$G$8:$G$407,Ingresos!$B$8:$B$407,">="&DATE(2027,10,1),Ingresos!$B$8:$B$407,"<="&DATE(2027,10,31))-SUMIFS(Gastos!$N$8:$N$407,Gastos!$B$8:$B$407,">="&DATE(2027,10,1),Gastos!$B$8:$B$407,"<="&DATE(2027,10,31)) | H27: 46689
B28: Noviembre | C28: =TARIFA_PLANA | D28: =BASE_MIN | E28: =IF(C28="Sí",TARIFA_PLANA_EUR,D28*TIPO_RETA/100) | F28: 4 | G28: =SUMIFS(Ingresos!$G$8:$G$407,Ingresos!$B$8:$B$407,">="&DATE(2027,11,1),Ingresos!$B$8:$B$407,"<="&DATE(2027,11,30))-SUMIFS(Gastos!$N$8:$N$407,Gastos!$B$8:$B$407,">="&DATE(2027,11,1),Gastos!$B$8:$B$407,"<="&DATE(2027,11,30)) | H28: 46721
B29: Diciembre | C29: =TARIFA_PLANA | D29: =BASE_MIN | E29: =IF(C29="Sí",TARIFA_PLANA_EUR,D29*TIPO_RETA/100) | F29: 4 | G29: =SUMIFS(Ingresos!$G$8:$G$407,Ingresos!$B$8:$B$407,">="&DATE(2027,12,1),Ingresos!$B$8:$B$407,"<="&DATE(2027,12,31))-SUMIFS(Gastos!$N$8:$N$407,Gastos!$B$8:$B$407,">="&DATE(2027,12,1),Gastos!$B$8:$B$407,"<="&DATE(2027,12,31)) | H29: 46752
B30: Total del año | E30: =SUM(CUOTA_MES) | G30: =SUM(G18:G29)
B31: El cargo se hace el último día hábil de cada mes (aquí, sin contar festivos). Puedes cambiar de base hasta seis veces al año.
B33: 3. Regularización estimada con tus rendimientos reales
B34: Rendimiento neto real del año, según tus libros (€) | C34: =MAX(0,'Renta 2027'!C8-'Renta 2027'!C9)
B35: Tramo que te corresponde de verdad | C35: =MIN(COUNT(T_RMIN),COUNTIF(T_RMAX,"<"&(C34*(1-GASTOS_GENERICOS/100)/12))+1)
B36: Cuota mínima de ese tramo × 12 (€) | C36: =INDEX(T_BMIN,C35)*TIPO_RETA/100*12
B37: Lo que has pagado (sin los meses de tarifa plana) (€) | C37: =SUMIFS(E18:E29,C18:C29,"<>Sí")
B38: Meses sin tarifa plana | C38: =COUNTIF(C18:C29,"<>Sí")
B39: Diferencia estimada: + te reclamarán / − te devolverán | C39: =C36/12*C38-C37 | D39: Orientativo. La Seguridad Social regulariza al año siguiente con los datos de Hacienda: solo devuelve si cotizaste por encima de la base máxima de tu tramo real; si cotizaste por una base mayor por elección, la diferencia no se devuelve.
B42: 4. Tabla de tramos 2027 (provisional: tabla de 2026)
B43: Tramo | C43: Rendimiento mensual desde | D43: Rendimiento mensual hasta | E43: Base mínima | F43: Base máxima | G43: Cuota mínima | H43: Cuota máxima
B44: Tramo 1 · reducida | C44: 0 | D44: 670 | E44: 653.59 | F44: 718.94 | G44: =E44*TIPO_RETA/100 | H44: =F44*TIPO_RETA/100
B45: Tramo 2 · reducida | C45: 670.01 | D45: 900 | E45: 718.95 | F45: 900 | G45: =E45*TIPO_RETA/100 | H45: =F45*TIPO_RETA/100
B46: Tramo 3 · reducida | C46: 900.01 | D46: 1166.7 | E46: 849.67 | F46: 1166.7 | G46: =E46*TIPO_RETA/100 | H46: =F46*TIPO_RETA/100
B47: Tramo 4 · general | C47: 1166.71 | D47: 1300 | E47: 950.98 | F47: 1300 | G47: =E47*TIPO_RETA/100 | H47: =F47*TIPO_RETA/100
B48: Tramo 5 · general | C48: 1300.01 | D48: 1500 | E48: 960.78 | F48: 1500 | G48: =E48*TIPO_RETA/100 | H48: =F48*TIPO_RETA/100
...

Sheet Renta 2027
B2: Estimación de la renta 2027 | D2: ImpuestoClaro
B3: Se declara entre abril y junio de 2028. Estimación directa simplificada, sin deducciones.
B7: Rendimiento de la actividad
B8: Ingresos del año | C8: =SUMIFS(Ingresos!$G$8:$G$407,Ingresos!$N$8:$N$407,ANIO)
B9: Gastos deducibles del libro | C9: =SUMIFS(Gastos!$N$8:$N$407,Gastos!$P$8:$P$407,ANIO)
B10: Rendimiento antes de la cuota | C10: =MAX(0,C8-C9)
B11: Cuota de autónomos del año | C11: =ROUND(CUOTA_ANUAL,2) | D11: Desde «Cuota autónomos»
B12: Rendimiento neto | C12: =MAX(0,C10-C11)
B13: Gastos de difícil justificación | C13: =MIN(C12*DJ_PCT/100,DJ_MAX) | D13: 5 % del rendimiento neto, máximo 2.000 € (art. 30 RIRPF)
B14: Base liquidable general | C14: =MAX(0,C12-C13)
B16: Mínimo personal y familiar
B17: Mínimo por descendientes | C17: =(IF(HIJOS>=1,MIN_DESC1,0)+IF(HIJOS>=2,MIN_DESC2,0)+IF(HIJOS>=3,MIN_DESC3,0)+IF(HIJOS>=4,MIN_DESC4,0)+MAX(0,HIJOS-4)*MIN_DESC4+MIN(HIJOS,HIJOS3)*MIN_MENOR3)*IF(HIJOS100="Sí",1,0.5)
B18: Mínimo personal y familiar estatal | C18: =MIN_PERSONAL+IF(EDAD>=65,MIN_65,0)+IF(EDAD>=75,MIN_75,0)+C17
B19: Mínimo personal y familiar autonómico | C19: =INDEX(CCAA_MINP,MATCH(CCAA,CCAA_COD,0))+IF(EDAD>=65,MIN_65,0)+IF(EDAD>=75,MIN_75,0)+C17 | D19: Algunas comunidades tienen un mínimo personal propio
B21: Cuota
B22: Cuota estatal | C22: =MAX(0,SUMPRODUCT((ESC_COD="ESTATAL")*(C14>ESC_DESDE)*(C14-ESC_DESDE)*ESC_DELTA)/100-SUMPRODUCT((ESC_COD="ESTATAL")*(MIN(C18,C14)>ESC_DESDE)*(MIN(C18,C14)-ESC_DESDE)*ESC_DELTA)/100)
B23: Cuota autonómica | C23: =MAX(0,SUMPRODUCT((ESC_COD=CCAA)*(C14>ESC_DESDE)*(C14-ESC_DESDE)*ESC_DELTA)/100-SUMPRODUCT((ESC_COD=CCAA)*(MIN(C19,C14)>ESC_DESDE)*(MIN(C19,C14)-ESC_DESDE)*ESC_DELTA)/100) | D23: ="Escala de "&CCAA_NOMBRE
B24: Bonificación (Ceuta y Melilla) | C24: =INDEX(CCAA_BONIF,MATCH(CCAA,CCAA_COD,0))
B25: Cuota íntegra total | C25: =(C22+C23)*(1-C24/100)
B26: Tipo medio sobre la base | C26: =IF(C14>0,C25/C14*100,0)
B28: Resultado de la declaración
B29: Retenciones de tus facturas | C29: =SUMIFS(Ingresos!$K$8:$K$407,Ingresos!$N$8:$N$407,ANIO)
B30: Pagos fraccionados (modelo 130) | C30: =PAGO130_1+PAGO130_2+PAGO130_3+PAGO130_4
B31: A PAGAR (+) o A DEVOLVER (−) | C31: =C25-C29-C30
B32: Lo que te queda en el año (tras cuota e IRPF) | C32: =C10-C11-C25
B33: Al mes | C33: =C32/12
B35: Estimación para un contribuyente que declara solo. No incluye otras rentas (nómina, alquileres, ahorro), deducciones estatales o autonómicas, planes de pensiones ni la tributación conjunta. Compárala siempre con el borrador de Renta WEB.

Sheet Calendario 2027
B2: Calendario fiscal 2027 | F2: ImpuestoClaro
B3: Fechas límite de presentación (con domiciliación, unos días antes). Marca «Sí» cuando lo hayas hecho.
B6: Fecha | C6: Día | D6: Modelos | E6: Qué es | F6: ¿Hecho?
B7: 46407 | C7: miércoles | D7: 111, 115, 123, 216 | E7: 111: Retenciones de trabajadores y profesionales que pagas tú; 115: Retenciones del alquiler de tu local u oficina · 4T 2026 retenciones
B8: 46416 | C8: viernes | D8: RETA | E8: Cargo de la cuota de autónomos de enero
B9: 46419 | C9: lunes | D9: 130, 131, 303, 349, 390, 180, 190, 193 | E9: 130: Pago fraccionado del IRPF (estimación directa); 303: Autoliquidación de IVA; 349: Operaciones intracomunitarias; 390: Resumen anual de IVA · Plazo del 30/31 de enero trasladado al lunes 1 de febrero por caer en fin de semana
B10: 46444 | C10: viernes | D10: RETA | E10: Cargo de la cuota de autónomos de febrero
B11: 46447 | C11: lunes | D11: 347 | E11: 347: Operaciones con terceros de más de 3.005,06 € · Plazo de febrero; 28-2-2027 es domingo
B12: 46477 | C12: miércoles | D12: RETA | E12: Cargo de la cuota de autónomos de marzo
B13: 46497 | C13: martes | D13: 111, 115, 123, 130, 131, 303, 349, 202 | E13: 111: Retenciones de trabajadores y profesionales que pagas tú; 115: Retenciones del alquiler de tu local u oficina; 130: Pago fraccionado del IRPF (estimación directa); 303: Autoliquidación de IVA; 349: Operaciones intracomunitarias · 1T 2027 y primer pago fraccionado IS
B14: 46507 | C14: viernes | D14: RETA | E14: Cargo de la cuota de autónomos de abril
B15: 46538 | C15: lunes | D15: RETA | E15: Cargo de la cuota de autónomos de mayo
B16: 46568 | C16: miércoles | D16: 100, 714 | E16: 100: Declaración de la renta (IRPF) · Fin previsto campaña Renta y Patrimonio 2026 (pendiente de orden)
B17: 46568 | C17: miércoles | D17: RETA | E17: Cargo de la cuota de autónomos de junio
B18: 46588 | C18: martes | D18: 111, 115, 123, 130, 131, 303, 349 | E18: 111: Retenciones de trabajadores y profesionales que pagas tú; 115: Retenciones del alquiler de tu local u oficina; 130: Pago fraccionado del IRPF (estimación directa); 303: Autoliquidación de IVA; 349: Operaciones intracomunitarias · 2T 2027
... B28: 46783 | C28: lunes | D28: 303, 130, 390 | E28: 4T de 2027: IVA, pago fraccionado y resumen anual de IVA
B30: En amarillo, lo que vence en los próximos 15 días; en rojo, lo vencido sin marcar. Fuente: calendario del contribuyente de la AEAT (AEAT - Calendario del contribuyente (reglas generales de plazos)). Campaña de Renta 2027: previsiblemente abril-30 de junio de 2028 (sin orden publicada). En 2027 se presenta la Renta 2026 (abril-30 junio 2027, previsto).

Sheet Parámetros
B2: Parámetros | D2: ImpuestoClaro
B3: Cifras de params/es/2027 a 2026-10-27. Si cambian, se publica una versión nueva del kit.
B6: Concepto | C6: Valor | D6: Fuente oficial
B7: Ejercicio
B8: Año del kit | C8: 2027 | D8: Ejercicio fiscal de los libros
B9: IVA
B10: Tipo general de IVA (%) | C10: 21 | D10: Ley 37/1992 del IVA (BOE)
B11: Tipo reducido de IVA (%) | C11: 10 | D11: Ley 37/1992 del IVA (BOE)
B12: Tipo superreducido de IVA (%) | C12: 4 | D12: Ley 37/1992 del IVA (BOE)
B13: Modelo 130
B14: Pago fraccionado sobre el rendimiento neto acumulado (%) | C14: 20 | D14: Ley 35/2006 del IRPF, art. 99; RIRPF art. 110
B15: Minoración: rendimiento del año anterior hasta (€), tramo 1 | C15: 9000 | D15: Reglamento del IRPF (RD 439/2007), art. 110.3.c
B16: Minoración por trimestre (€), tramo 1 | C16: 100 | D16: Reglamento del IRPF (RD 439/2007), art. 110.3.c
B17: Minoración: rendimiento del año anterior hasta (€), tramo 2 | C17: 10000 | D17: Reglamento del IRPF (RD 439/2007), art. 110.3.c
B18: Minoración por trimestre (€), tramo 2 | C18: 75 | D18: Reglamento del IRPF (RD 439/2007), art. 110.3.c
B19: Minoración: rendimiento del año anterior hasta (€), tramo 3 | C19: 11000 | D19: Reglamento del IRPF (RD 439/2007), art. 110.3.c
B20: Minoración por trimestre (€), tramo 3 | C20: 50 | D20: Reglamento del IRPF (RD 439/2007), art. 110.3.c
B21: Minoración: rendimiento del año anterior hasta (€), tramo 4 | C21: 12000 | D21: Reglamento del IRPF (RD 439/2007), art. 110.3.c
B22: Minoración por trimestre (€), tramo 4 | C22: 25 | D22: Reglamento del IRPF (RD 439/2007), art. 110.3.c
B23: Cuota de autónomos (RETA)
B24: Tipo de cotización total (%) | C24: 31.6 | D24: Orden PJC/297/2026, de 30 de marzo, normas de cotización 2026 (BOE 31/03/2026, BOE-A-2026-7296); RDL 3/2026 art. 3 · provisional: tabla de 2026
B25: Tarifa plana (€ al mes) | C25: 80 | D25: Orden PJC/297/2026, de 30 de marzo, normas de cotización 2026 (BOE 31/03/2026, BOE-A-2026-7296); RDL 3/2026 art. 3
B26: Deducción por gastos genéricos para el tramo (%) | C26: 7 | D26: Orden PJC/297/2026, de 30 de marzo, normas de cotización 2026 (BOE 31/03/2026, BOE-A-2026-7296); RDL 3/2026 art. 3
B27: IRPF: estimación directa simplificada
B28: Gastos de difícil justificación (%) | C28: 5 | D28: AEAT - Estimación directa simplificada
B29: Gastos de difícil justificación, máximo (€) | C29: 2000 | D29: AEAT - Estimación directa simplificada
B30: IRPF: mínimo personal y familiar (estatal)
B31: Mínimo del contribuyente (€) | C31: 5550 | D31: AEAT Manual Renta 2025 - cuadro de mínimos estatal y autonómicos
B32: Incremento por edad: 65 años o más (€) | C32: 1150 | D32: AEAT Manual Renta 2025 - cuadro de mínimos estatal y autonómicos
B33: Incremento adicional: 75 años o más (€) | C33: 1400 | D33: AEAT Manual Renta 2025 - cuadro de mínimos estatal y autonómicos
B34: Mínimo por descendiente: 1.º (€) | C34: 2400 | D34: AEAT Manual Renta 2025 - cuadro de mínimos estatal y autonómicos
B35: Mínimo por descendiente: 2.º (€) | C35: 2700 | D35: AEAT Manual Renta 2025 - cuadro de mínimos estatal y autonómicos
B36: Mínimo por descendiente: 3.º (€) | C36: 4000 | D36: AEAT Manual Renta 2025 - cuadro de mínimos estatal y autonómicos
B37: Mínimo por descendiente: 4.º y siguientes (€) | C37: 4500 | D37: AEAT Manual Renta 2025 - cuadro de mínimos estatal y autonómicos
B38: Incremento por descendiente menor de 3 años (€) | C38: 2800 | D38: AEAT Manual Renta 2025 - cuadro de mínimos estatal y autonómicos

Sheet Escalas IRPF
B2: Escalas del IRPF | K2: ImpuestoClaro
B3: Escala estatal y autonómicas de la base general. Las fórmulas usan la columna «Diferencia de tipo»: cuota = Σ (base − desde) × diferencia.
B6: Código | C6: Escala | D6: Desde (€) | E6: Tipo (%) | F6: Diferencia de tipo | H6: Código | I6: Comunidad | J6: Mínimo personal autonómico (€) | K6: Bonificación de la cuota (%)
B7: ESTATAL | C7: Estatal | D7: 0 | E7: 9.5 | F7: =E7 | H7: AN | I7: Andalucía | J7: 5790 | K7: 0
B8: ESTATAL | C8: Estatal | D8: 12450 | E8: 12 | F8: =E8-E7 | H8: AR | I8: Aragón | J8: 5550 | K8: 0
B9: ESTATAL | C9: Estatal | D9: 20200 | E9: 15 | F9: =E9-E8 | H9: AS | I9: Principado de Asturias | J9: 6105 | K9: 0
B10: ESTATAL | C10: Estatal | D10: 35200 | E10: 18.5 | F10: =E10-E9 | H10: IB | I10: Illes Balears | J10: 6105 | K10: 0
B11: ESTATAL | C11: Estatal | D11: 60000 | E11: 22.5 | F11: =E11-E10 | H11: CN | I11: Canarias | J11: 5606 | K11: 0
B12: ESTATAL | C12: Estatal | D12: 300000 | E12: 24.5 | F12: =E12-E11 | H12: CB | I12: Cantabria | J12: 5550 | K12: 0
B13: AN | C13: Andalucía | D13: 0 | E13: 9.5 | F13: =E13 | H13: CL | I13: Castilla y León | J13: 5550 | K13: 0
B14: AN | C14: Andalucía | D14: 13000 | E14: 12 | F14: =E14-E13 | H14: CM | I14: Castilla-La Mancha | J14: 5550 | K14: 0
B15: AN | C15: Andalucía | D15: 21100 | E15: 15 | F15: =E15-E14 | H15: CT | I15: Cataluña | J15: 5550 | K15: 0
B16: AN | C16: Andalucía | D16: 35200 | E16: 18.5 | F16: =E16-E15 | H16: EX | I16: Extremadura | J16: 5550 | K16: 0
B17: AN | C17: Andalucía | D17: 60000 | E17: 22.5 | F17: =E17-E16 | H17: GA | I17: Galicia | J17: 5789 | K17: 0
B18: AR | C18: Aragón | D18: 0 | E18: 9.5 | F18: =E18 | H18: MD | I18: Comunidad de Madrid | J18: 5956.65 | K18: 0
B19: AR | C19: Aragón | D19: 13072.5 | E19: 12 | F19: =E19-E18 | H19: MC | I19: Región de Murcia | J19: 5550 | K19: 0
B20: AR | C20: Aragón | D20: 21210 | E20: 15 | F20: =E20-E19 | H20: RI | I20: La Rioja | J20: 5550 | K20: 0
B21: AR | C21: Aragón | D21: 36960 | E21: 18.5 | F21: =E21-E20 | H21: VC | I21: Comunitat Valenciana | J21: 6105 | K21: 0
B22: AR | C22: Aragón | D22: 52500 | E22: 20.5 | F22: =E22-E21 | H22: CE_ML | I22: Ceuta y Melilla | J22: =MIN_PERSONAL | K22: 60
B23: AR | C23: Aragón | D23: 60000 | E23: 23 | F23: =E23-E22
B24: AR | C24: Aragón | D24: 80000 | E24: 24 | F24: =E24-E23 | I24: Fuentes: escala estatal, art. 63 LIRPF; autonómicas, Manual práctico de Renta de la AEAT y leyes de cada comunidad. Detalle y notas en params/es/2027/fiscal.json.
B25: AR | C25: Aragón | D25: 90000 | E25: 25 | F25: =E25-E24
B26: AR | C26: Aragón | D26: 130000 | E26: 25.5 | F26: =E26-E25
B27: AS | C27: Principado de Asturias | D27: 0 | E27: 9 | F27: =E27
B28: AS | C28: Principado de Asturias | D28: 12450 | E28: 12 | F28: =E28-E27
B29: AS | C29: Principado de Asturias | D29: 17707.2 | E29: 14 | F29: =E29-E28
B30: AS | C30: Principado de Asturias | D30: 33007.2 | E30: 19.2 | F30: =E30-E29
B31: AS | C31: Principado de Asturias | D31: 53407.2 | E31: 21.5 | F31: =E31-E30
B32: AS | C32: Principado de Asturias | D32: 70000 | E32: 22.5 | F32: =E32-E31
B33: AS | C33: Principado de Asturias | D33: 90000 | E33: 25 | F33: =E33-E32
B34: AS | C34: Principado de Asturias | D34: 175000 | E34: 26 | F34: =E34-E33
B35: IB | C35: Illes Balears | D35: 0 | E35: 9 | F35: =E35
B36: IB | C36: Illes Balears | D36: 10000 | E36: 11.25 | F36: =E36-E35
B37: IB | C37: Illes Balears | D37: 18000 | E37: 14.25 | F37: =E37-E36
B38: IB | C38: Illes Balears | D38: 30000 | E38: 17.5 | F38: =E38-E37
B39: IB | C39: Illes Balears | D39: 48000 | E39: 19 | F39: =E39-E38
B40: IB | C40: Illes Balears | D40: 70000 | E40: 21.75 | F40: =E40-E39
B41: IB | C41: Illes Balears | D41: 90000 | E41: 22.75 | F41: =E41-E40
B42: IB | C42: Illes Balears | D42: 120000 | E42: 23.75 | F42: =E42-E41
B43: IB | C43: Illes Balears | D43: 175000 | E43: 24.75 | F43: =E43-E42
...
